Workbook
Name KANTOR: #REF!
Name MA.5120_I: #REF!
Name MA.5120_I: #REF!
Name MA.5120_I: #REF!
Name MA.5120_II: #REF!
Name MA.5120_II: #REF!
Name MA.5120_II: #REF!
Name MA.5125: #REF!
Name MA.5125: #REF!
Name MA.5125: #REF!
Name MM.5120_I: #REF!
Name MM.5120_I: #REF!
Name MM.5120_I: #REF!
Name MM.5120_II: #REF!
Name MM.5120_II: #REF!
Name MM.5120_II: #REF!
Name MM.5125: #REF!
Name MM.5125: #REF!
Name MM.5125: #REF!
Name MS.5120_I: #REF!
Name MS.5120_I: #REF!
Name MS.5120_I: #REF!
Name MS.5120_II: #REF!
Name MS.5120_II: #REF!
Name MS.5120_II: #REF!
Name MS.5125: #REF!
Name MS.5125: #REF!
Name MS.5125: #REF!
Name MU.5120_I: #REF!
Name MU.5120_I: #REF!
Name MU.5120_I: #REF!
Name MU.5120_II: #REF!
Name MU.5120_II: #REF!
Name MU.5120_II: #REF!
Name MU.5125: #REF!
Name MU.5125: #REF!
Name MU.5125: #REF!
Name PT.ASDP__PESERO: #REF!
Name vvzh: [1]SEMUMU!$L$116

Sheet Prognosa (2)
B2: PT. ASDP INDONESIA FERRY (PERSERO)
B3: TABEL PENYUSUNAN PROGNOSA RKAC BIAYA PERAWATAN KAPAL CABANG LUWUK TAHUN 2024
B5: NO | C5: NAMA KAPAL | D5: JENIS BIAYA PEMELIHARAAN | F5: RKA 2023 | G5: TOTAL BIAYA | H5: USULAN RKAC 2024 | I5: ESTIMASI KEBUTUHAN ANGGARAN BULAN AGUSTUS SD DESEMBER TAHUN 2023 | K5: PROGNOSA | M5: DEVIASI PROGNOSA TERHADAP RKAC 2023 | O5: DEVIASI USULAN RKAC 2024
I6: Berdasarkan Realisasi PJK (Versi B) | J6: Perhitungan RKAC (Versi B) | K6: Versi A | L6: Versi B | M6: Versi A (%) | N6: Versi B (%) | O6: TERHADAP RKAC 2024 (%) | P6: TERHADAP PROGNOSA VERSI A (%) | Q6: TERHADAP PROGNOSA VERSI B (%)
B7: 1 | C7: 2 | D7: 3 | F7: 4 | G7: 5 | H7: 6 | I7: 7 | J7: 8 | K7: 9 (5+7) | L7: 10 (5 + 8) | M7: 11 (8:4) | N7: 12 (9:4) | O7: 12 (6:4) | P7: 13 (6:8) | Q7: 14 (6:9)
B9: 1 | C9: KMP. MOINIT | D9: 1 | E9: Bahan Pelumas | F9: =[2]REKAP!$F$11 -> 2.6084556e+08 | G9: ='[3]PROGNOSA (2)'!$D$54 -> 70508220 | H9: ='[4]REKAPITULASI KAPAL'!I9 -> 2.2353116e+08 | J9: =(F9/12)*5 -> 1.0868565e+08 | L9: =J9+G9 -> 1.7919387e+08 | M9: =K9/F9 -> 0 | N9: =L9/F9 -> 0.68697305 | O9: =H9/F9 -> 0.85694831 | P9: =H9/K9 -> #DIV/0! | Q9: =H9/L9 -> 1.2474264
D10: 2 | E10: Kapal RO-RO/Penyeberangan | F10: 994766768 | G10: ='[3]PROGNOSA (2)'!$D$55 -> 801138610 | H10: ='[4]REKAPITULASI KAPAL'!I14 -> 9.8073037e+08 | L10: =J10+G10 -> 801138610 | M10: =K10/F10 -> 0 | N10: =L10/F10 -> 0.80535321 | O10: =H10/F10 -> 0.98588976 | P10: =H10/K10 -> #DIV/0! | Q10: =H10/L10 -> 1.2241706
D11: 3 | E11: Akomodasi, Peralatan, dan Perlengkapan Kapal | F11: 294773975 | G11: ='[3]PROGNOSA (2)'!$D$56 -> 177514920 | H11: ='[4]REKAPITULASI KAPAL'!$I$20 -> 469166650 | J11: =(F11/12)*5 -> 1.2282249e+08 | L11: =J11+G11 -> 3.0033741e+08 | M11: =K11/F11 -> 0 | N11: =L11/F11 -> 1.0188736 | O11: =H11/F11 -> 1.5916149 | P11: =H11/K11 -> #DIV/0! | Q11: =H11/L11 -> 1.5621319
D12: 4 | E12: Permesinan dan Kelistrikan Kapal | F12: 306018000 | G12: ='[3]PROGNOSA (2)'!$D$57 -> 179754078 | H12: ='[4]REKAPITULASI KAPAL'!$I$27 -> 443685430 | J12: =(F12/12)*5 -> 127507500 | L12: =J12+G12 -> 307261578 | M12: =K12/F12 -> 0 | N12: =L12/F12 -> 1.0040637 | O12: =H12/F12 -> 1.4498671 | P12: =H12/K12 -> #DIV/0! | Q12: =H12/L12 -> 1.4439991
D13: 5 | E13: Mobilisasi Dlm rangka Docking | F13: 149477700 | G13: ='[3]PROGNOSA (2)'!$D$53 -> 186036000 | H13: ='[4]REKAPITULASI KAPAL'!$I$33 -> 218400000 | L13: =J13+G13 -> 186036000 | M13: =K13/F13 -> 0 | N13: =L13/F13 -> 1.2445736 | O13: =H13/F13 -> 1.4610875 | P13: =H13/K13 -> #DIV/0! | Q13: =H13/L13 -> 1.1739663 | R13: =K13/G13 -> 0
E14: Jumlah | F14: =SUM(F9:F13) -> 2.005882e+09 | G14: =SUM(G9:G13) -> 1414951828 | H14: =SUM(H9:H13) -> 2.3355136e+09 | I14: =SUM(I9:I13) -> 0 | J14: =SUM(J9:J13) -> 3.5901564e+08 | K14: =SUM(K9:K13) -> 0 | L14: =SUM(L9:L13) -> 1.7739675e+09 | M14: =K14/F14 -> 0 | N14: =L14/G14 -> 1.2537299 | O14: =H14/F14 -> 1.1643325 | P14: =H14/K14 -> #DIV/0! | Q14: =H14/L14 -> 1.3165482
B16: 2 | C16: KMP. TUNA TOMINI | D16: 1 | E16: Bahan Pelumas | F16: =[2]REKAP!$F$18 -> 2.6134556e+08 | G16: ='[3]PROGNOSA (2)'!D5 -> 94192480 | H16: ='[4]REKAPITULASI KAPAL'!$G$9 -> 2.0458355e+08 | J16: =(F16/12)*5 -> 1.0889398e+08 | L16: =J16+G16 -> 2.0308646e+08 | M16: =K16/F16 -> 0 | N16: =L16/F16 -> 0.77708022 | O16: =H16/F16 -> 0.7828086 | P16: =H16/K16 -> #DIV/0! | Q16: =H16/L16 -> 1.0073717
D17: 2 | E17: Kapal RO-RO/Penyeberangan | F17: =908852460 -> 908852460 | G17: ='[3]PROGNOSA (2)'!D6 -> 1661115776 | H17: ='[4]REKAPITULASI KAPAL'!$G$14 -> 1175203807 | L17: =J17+G17 -> 1661115776 | M17: =K17/F17 -> 0 | N17: =L17/F17 -> 1.8277068 | O17: =H17/F17 -> 1.2930634 | P17: =H17/K17 -> #DIV/0! | Q17: =H17/L17 -> 0.70747857
D18: 3 | E18: Akomodasi, Peralatan, dan Perlengkapan Kapal | F18: =278355450 -> 278355450 | G18: ='[3]PROGNOSA (2)'!D7 -> 315266188 | H18: ='[4]REKAPITULASI KAPAL'!$G$20 -> 532726900 | J18: =(F18/12)*5 -> 1.1598144e+08 | L18: =J18+G18 -> 4.3124763e+08 | M18: =K18/F18 -> 0 | N18: =L18/F18 -> 1.5492696 | O18: =H18/F18 -> 1.9138368 | P18: =H18/K18 -> #DIV/0! | Q18: =H18/L18 -> 1.2353156
D19: 4 | E19: Permesinan dan Kelistrikan Kapal | F19: =243024000 -> 243024000 | G19: ='[3]PROGNOSA (2)'!D8 -> 220917700 | H19: ='[4]REKAPITULASI KAPAL'!$G$27 -> 478047520 | J19: =(F19/12)*5 -> 101260000 | L19: =J19+G19 -> 322177700 | M19: =K19/F19 -> 0 | N19: =L19/F19 -> 1.3257032 | O19: =H19/F19 -> 1.9670795 | P19: =H19/K19 -> #DIV/0! | Q19: =H19/L19 -> 1.4838008
D20: 5 | E20: Mobilisasi Dlm rangka Docking | F20: =109477700 -> 109477700 | G20: ='[3]PROGNOSA (2)'!$D$4 -> 115495500 | H20: ='[4]REKAPITULASI KAPAL'!$G$33 -> 250000000 | L20: =J20+G20 -> 115495500 | M20: =K20/F20 -> 0 | N20: =L20/F20 -> 1.0549683 | O20: =H20/F20 -> 2.2835701 | P20: =H20/K20 -> #DIV/0! | Q20: =H20/L20 -> 2.1645865
E21: Jumlah | F21: =SUM(F16:F20) -> 1.8010552e+09 | G21: =SUM(G16:G20) -> 2406987644 | H21: =SUM(H16:H20) -> 2.6405618e+09 | I21: =SUM(I16:I20) -> 0 | J21: =SUM(J16:J20) -> 3.2613542e+08 | K21: =SUM(K16:K20) -> 0 | L21: =SUM(L16:L20) -> 2.7331231e+09 | M21: =K21/F21 -> 0 | N21: =L21/G21 -> 1.1354953 | O21: =H21/F21 -> 1.4661193 | P21: =H21/K21 -> #DIV/0! | Q21: =H21/L21 -> 0.96613351
B23: 3 | C23: KMP. CENGKIH AFO | D23: 1 | E23: Bahan Pelumas | F23: =[2]REKAP!$F$25 -> 2.6134556e+08 | G23: ='[3]PROGNOSA (2)'!D29 -> 69992480 | H23: ='[4]REKAPITULASI KAPAL'!$E$9 -> 2.2394111e+08 | J23: =(F23/12)*5 -> 1.0889398e+08 | L23: =J23+G23 -> 1.7888646e+08 | M23: =K23/F23 -> 0 | N23: =L23/F23 -> 0.68448251 | O23: =H23/F23 -> 0.85687743 | P23: =H23/K23 -> #DIV/0! | Q23: =H23/L23 -> 1.2518617
D24: 2 | E24: Kapal RO-RO/Penyeberangan | F24: 849098940 | G24: ='[3]PROGNOSA (2)'!D30 -> 1838757695 | H24: ='[4]REKAPITULASI KAPAL'!$E$14 -> 1068499860 | L24: =J24+G24 -> 1838757695 | M24: =K24/F24 -> 0 | N24: =L24/F24 -> 2.16554 | O24: =H24/F24 -> 1.2583926 | P24: =H24/K24 -> #DIV/0! | Q24: =H24/L24 -> 0.58109878
D25: 3 | E25: Akomodasi, Peralatan, dan Perlengkapan Kapal | F25: 262104333 | G25: ='[3]PROGNOSA (2)'!D31 -> 249673250 | H25: ='[4]REKAPITULASI KAPAL'!$E$20 -> 518217900 | J25: =(F25/12)*5 -> 1.0921014e+08 | L25: =J25+G25 -> 3.5888339e+08 | M25: =K25/F25 -> 0 | N25: =L25/F25 -> 1.3692387 | O25: =H25/F25 -> 1.9771436 | P25: =H25/K25 -> #DIV/0! | Q25: =H25/L25 -> 1.4439729
D26: 4 | E26: Permesinan dan Kelistrikan Kapal | F26: 316778000 | G26: ='[3]PROGNOSA (2)'!D32 -> 297756800 | H26: ='[4]REKAPITULASI KAPAL'!$E$27 -> 4.7731119e+08 | J26: =(F26/12)*5 -> 1.3199083e+08 | L26: =J26+G26 -> 4.2974763e+08 | M26: =K26/F26 -> 0 | N26: =L26/F26 -> 1.3566208 | O26: =H26/F26 -> 1.5067687 | P26: =H26/K26 -> #DIV/0! | Q26: =H26/L26 -> 1.1106779
D27: 5 | E27: Mobilisasi Dlm rangka Docking | F27: 126554300 | G27: ='[3]PROGNOSA (2)'!$D$28 -> 186800000 | H27: ='[4]REKAPITULASI KAPAL'!$E$33 -> 217000000 | L27: =J27+G27 -> 186800000 | M27: =K27/F27 -> 0 | N27: =L27/F27 -> 1.4760463 | O27: =H27/F27 -> 1.714679 | P27: =H27/K27 -> #DIV/0! | Q27: =H27/L27 -> 1.1616702
E28: Jumlah | F28: =SUM(F23:F27) -> 1.8158811e+09 | G28: =SUM(G23:G27) -> 2642980225 | H28: =SUM(H23:H27) -> 2.5049701e+09 | I28: =SUM(I23:I27) -> 0 | J28: =SUM(J23:J27) -> 3.5009495e+08 | K28: =SUM(K23:K27) -> 0 | L28: =SUM(L23:L27) -> 2.9930752e+09 | M28: =K28/F28 -> 0 | N28: =L28/G28 -> 1.1324622 | O28: =H28/F28 -> 1.3794791 | P28: =H28/K28 -> #DIV/0! | Q28: =H28/L28 -> 0.83692186
B30: 4 | C30: KMP. TANJUNG API | D30: 1 | E30: Bahan Pelumas | F30: =[2]REKAP!$F$32 -> 2.482551e+08 | G30: ='[3]PROGNOSA (2)'!D17 -> 86892480 | H30: ='[4]REKAPITULASI KAPAL'!$H$9 -> 2.1598029e+08 | J30: =(F30/12)*5 -> 1.0343963e+08 | L30: =J30+G30 -> 1.9033211e+08 | M30: =K30/F30 -> 0 | N30: =L30/F30 -> 0.76667953 | O30: =H30/F30 -> 0.86999336 | P30: =H30/K30 -> #DIV/0! | Q30: =H30/L30 -> 1.1347549
D31: 2 | E31: Kapal RO-RO/Penyeberangan | F31: 790664322 | G31: ='[3]PROGNOSA (2)'!D18 -> 884763187 | H31: ='[4]REKAPITULASI KAPAL'!$H$14 -> 928884137 | L31: =J31+G31 -> 884763187 | M31: =K31/F31 -> 0 | N31: =L31/F31 -> 1.1190124 | O31: =H31/F31 -> 1.1748148 | P31: =H31/K31 -> #DIV/0! | Q31: =H31/L31 -> 1.0498675
D32: 3 | E32: Akomodasi, Peralatan, dan Perlengkapan Kapal | F32: 224275761 | G32: ='[3]PROGNOSA (2)'!D19 -> 169048600 | H32: ='[4]REKAPITULASI KAPAL'!$H$20 -> 401360000 | J32: =(F32/12)*5 -> 93448234 | L32: =J32+G32 -> 2.6249683e+08 | M32: =K32/F32 -> 0 | N32: =L32/F32 -> 1.17042 | O32: =H32/F32 -> 1.7895826 | P32: =H32/K32 -> #DIV/0! | Q32: =H32/L32 -> 1.5290089
D33: 4 | E33: Permesinan dan Kelistrikan Kapal | F33: 322506800 | G33: ='[3]PROGNOSA (2)'!D20 -> 211288362 | H33: ='[4]REKAPITULASI KAPAL'!$H$27 -> 450467330 | J33: =(F33/12)*5 -> 1.3437783e+08 | L33: =J33+G33 -> 3.456662e+08 | M33: =K33/F33 -> 0 | N33: =L33/F33 -> 1.0718106 | O33: =H33/F33 -> 1.3967685 | P33: =H33/K33 -> #DIV/0! | Q33: =H33/L33 -> 1.303186
D34: 5 | E34: Mobilisasi Dlm rangka Docking | F34: 125798050 | G34: ='[3]PROGNOSA (2)'!$D$16 -> 18348000 | H34: ='[4]REKAPITULASI KAPAL'!$H$33 -> 1.9070544e+08 | L34: =J34+G34 -> 18348000 | M34: =K34/F34 -> 0 | N34: =L34/F34 -> 0.14585282 | O34: =H34/F34 -> 1.515965 | P34: =H34/K34 -> #DIV/0! | Q34: =H34/L34 -> 10.3938
E35: Jumlah | F35: =SUM(F30:F34) -> 1.7115e+09 | G35: =SUM(G30:G34) -> 1370340629 | H35: =SUM(H30:H34) -> 2.1873972e+09 | I35: =SUM(I30:I34) -> 0 | J35: =SUM(J30:J34) -> 3.3126569e+08 | K35: =SUM(K30:K34) -> 0 | L35: =SUM(L30:L34) -> 1.7016063e+09 | M35: =K35/F35 -> 0 | N35: =L35/G35 -> 1.2417397 | O35: =H35/F35 -> 1.2780585 | P35: =H35/K35 -> #DIV/0! | Q35: =H35/L35 -> 1.2854896
B37: 5 | C37: KMP. TELUK TOLO | D37: 1 | E37: Bahan Pelumas | F37: =[2]REKAP!$F$46 -> 2.6134556e+08 | G37: ='[3]PROGNOSA (2)'!D42 -> 103192480 | H37: ='[4]REKAPITULASI KAPAL'!$J$9 -> 2.270459e+08 | J37: =(F37/12)*5 -> 1.0889398e+08 | L37: =J37+G37 -> 2.1208646e+08 | M37: =K37/F37 -> 0 | N37: =L37/F37 -> 0.81151738 | O37: =H37/F37 -> 0.86875744 | P37: =H37/K37 -> #DIV/0! | Q37: =H37/L37 -> 1.0705346
D38: 2 | E38: Kapal RO-RO/Penyeberangan | F38: 847824785 | G38: ='[3]PROGNOSA (2)'!D43 -> 1252641038 | H38: ='[4]REKAPITULASI KAPAL'!$J$14 -> 9.8022995e+08 | L38: =J38+G38 -> 1252641038 | M38: =K38/F38 -> 0 | N38: =L38/F38 -> 1.4774763 | O38: =H38/F38 -> 1.1561704 | P38: =H38/K38 -> #DIV/0! | Q38: =H38/L38 -> 0.78253061 | T38: =338697163/2 -> 1.6934858e+08
D39: 3 | E39: Akomodasi, Peralatan, dan Perlengkapan Kapal | F39: 315284392 | G39: ='[3]PROGNOSA (2)'!D44 -> 36200500 | H39: ='[4]REKAPITULASI KAPAL'!$J$20 -> 424380600 | J39: =(F39/12)*5 -> 1.313685e+08 | L39: =J39+G39 -> 1.67569e+08 | M39: =K39/F39 -> 0 | N39: =L39/F39 -> 0.53148523 | O39: =H39/F39 -> 1.3460248 | P39: =H39/K39 -> #DIV/0! | Q39: =H39/L39 -> 2.5325723 | T39: 74453308
D40: 4 | E40: Permesinan dan Kelistrikan Kapal | F40: 319556100 | G40: ='[3]PROGNOSA (2)'!D45 -> 80313000 | H40: ='[4]REKAPITULASI KAPAL'!$J$27 -> 406756495 | J40: =(F40/12)*5 -> 133148375 | L40: =J40+G40 -> 213461375 | M40: =K40/F40 -> 0 | N40: =L40/F40 -> 0.66799343 | O40: =H40/F40 -> 1.2728798 | P40: =H40/K40 -> #DIV/0! | Q40: =H40/L40 -> 1.9055274 | T40: 79000000
D41: 5 | E41: Mobilisasi Dlm rangka Docking | F41: 222399646 | G41: ='[3]PROGNOSA (2)'!$D$41 -> 116550000 | H41: ='[4]REKAPITULASI KAPAL'!$J$33 -> 233000000 | L41: =J41+G41 -> 116550000 | M41: =K41/F41 -> 0 | N41: =L41/F41 -> 0.52405659 | O41: =H41/F41 -> 1.0476635 | P41: =H41/K41 -> #DIV/0! | Q41: =H41/L41 -> 1.999142 | T41: 16175000
E42: Jumlah | F42: =SUM(F37:F41) -> 1.9664105e+09 | G42: =SUM(G37:G41) -> 1588897018 | H42: =SUM(H37:H41) -> 2.2714129e+09 | I42: =SUM(I37:I41) -> 0 | J42: =SUM(J37:J41) -> 3.7341085e+08 | K42: =SUM(K37:K41) -> 0 | L42: =SUM(L37:L41) -> 1.9623079e+09 | M42: =K42/F42 -> 0 | N42: =L42/G42 -> 1.2350126 | O42: =H42/F42 -> 1.1551062 | P42: =H42/K42 -> #DIV/0! | Q42: =H42/L42 -> 1.1575212 | S42: Kapal Roro | T42: =SUM(T38:T41) -> 3.3897689e+08
S43: BBM | T43: 78642396
B44: 6 | C44: KMP. DOLOSI | D44: 1 | E44: Bahan Pelumas | F44: =[2]REKAP!$F$39 -> 2.4626268e+08 | G44: ='[3]PROGNOSA (2)'!D67 -> 70508220 | H44: ='[4]REKAPITULASI KAPAL'!$F$9 -> 2.319959e+08 | J44: =(F44/12)*5 -> 1.0260945e+08 | L44: =J44+G44 -> 1.7311767e+08 | M44: =K44/F44 -> 0 | N44: =L44/F44 -> 0.70297972 | O44: =H44/F44 -> 0.94206682 | P44: =H44/K44 -> #DIV/0! | Q44: =H44/L44 -> 1.3401053 | S44: Deck | T44: 134713425 | V44: April | W44: Mei | X44: Juni | Y44: Juli
D45: 2 | E45: Kapal RO-RO/Penyeberangan | F45: 876755778 | G45: ='[3]PROGNOSA (2)'!D68 -> 653548850 | H45: ='[4]REKAPITULASI KAPAL'!$F$14 -> 9.5806095e+08 | L45: =J45+G45 -> 653548850 | M45: =K45/F45 -> 0 | N45: =L45/F45 -> 0.74541721 | O45: =H45/F45 -> 1.0927341 | P45: =H45/K45 -> #DIV/0! | Q45: =H45/L45 -> 1.4659363 | S45: Mesin | T45: 99294580 | V45: 28744815 | W45: 21600000 | X45: 32400000 | Y45: 45040000 | Z45: =SUM(V45:Y45) -> 127784815 | AA45: =SUM(W45:Y45) -> 99040000
D46: 3 | E46: Akomodasi, Peralatan, dan Perlengkapan Kapal | F46: 299803810 | G46: ='[3]PROGNOSA (2)'!D69 -> 213177250 | H46: ='[4]REKAPITULASI KAPAL'!$F$20 -> 422892400 | J46: =(F46/12)*5 -> 1.2491825e+08 | L46: =J46+G46 -> 3.380955e+08 | M46: =K46/F46 -> 0 | N46: =L46/F46 -> 1.1277225 | O46: =H46/F46 -> 1.4105638 | P46: =H46/K46 -> #DIV/0! | Q46: =H46/L46 -> 1.2508075 | S46: Pelumas | T46: 11594033 | V46: 0 | W46: 0 | X46: 0 | Y46: 0 | Z46: =SUM(V46:Y46) -> 0
D47: 4 | E47: Permesinan dan Kelistrikan Kapal | F47: 338927600 | G47: ='[3]PROGNOSA (2)'!D70 -> 232968700 | H47: ='[4]REKAPITULASI KAPAL'!$F$27 -> 424053070 | J47: =(F47/12)*5 -> 1.4121983e+08 | L47: =J47+G47 -> 3.7418853e+08 | M47: =K47/F47 -> 0 | N47: =L47/F47 -> 1.1040368 | O47: =H47/F47 -> 1.2511612 | P47: =H47/K47 -> #DIV/0! | Q47: =H47/L47 -> 1.1332605 | V47: 15583450 | W47: 4572000 | X47: 65747000 | Y47: 37969019 | Z47: =SUM(V47:Y47) -> 1.2387147e+08 | AA47: =SUM(W47:Y47) -> 1.0828802e+08
...

Sheet data Prognosa rutin real (2)
B2: PT. ASDP INDONESIA FERRY (PERSERO)
B3: TABEL REALISASI BIAYA PERAWATAN KAPAL CABANG LUWUK TAHUN 2023
G5: REALISASI BIAYA JANUARI S/D JULI 2023 | O5: ESTIMATE AGUS S/D DES 2023
B6: NO | C6: NAMA KAPAL | D6: JENIS BIAYA PEMELIHARAAN | F6: RKA 2023 | G6: JANUARI | H6: FEBRUARI | I6: MARET | J6: APRIL | K6: MEI | L6: JUNI | M6: JULI | N6: TOTAL REALISASI BIAYA JAN S/D JULI 2023 | O6: AGUS | P6: SEPT | Q6: OKT | R6: NOP | S6: DES | T6: TOTAL ESTIMATE AGUS S/D DES 2023 | U6: PROGNOSA 2023 | V6: PRESENTASE PENYERAPAN RKAC | AE6: REALISASI BIAYA
B8: 1 | C8: KMP. MOINIT | D8: 1 | E8: Bahan Pelumas | F8: =[2]REKAP!$F$11 -> 2.6084556e+08 | I8: =[5]MOINIT!$E$51 -> 15900000 | K8: =[6]MOINIT!$E$51 -> 23210000 | M8: =[7]MOINIT!$E$53 -> 16300000 | N8: =SUM(G8:M8) -> 55410000 | O8: =F8/12 -> 21737130 | P8: =O8 -> 21737130 | Q8: =P8 -> 21737130 | R8: =Q8 -> 21737130 | S8: =R8 -> 21737130 | T8: =SUM(O8:S8) -> 1.0868565e+08 | U8: =T8+N8 -> 1.6409565e+08 | V8: =U8/F8 -> 0.62909122 | AE8: =[8]Prognosa!G9 -> 70508220 | AF8: =AE8-N8 -> 15098220 | AG8: 18774450 | AP8: ='data Prognosa rutin'!U8 -> 1.7919387e+08 | AQ8: ='data Prognosa rutin'!V8 -> 0.68697305
D9: 2 | E9: Kapal RO-RO/Penyeberangan | F9: 994766768 | M9: =[7]MOINIT!E61 -> 337046500 | N9: =SUM(G9:M9) -> 337046500 | P9: 23500000 | T9: =SUM(O9:S9) -> 23500000 | U9: =T9+N9 -> 360546500 | V9: =U9/F9 -> 0.36244325 | AE9: =[8]Prognosa!G10 -> 801138610 | AF9: =AE9-N9 -> 464092110 | AG9: 45140920 | AP9: ='data Prognosa rutin'!U9 -> 801138610 | AQ9: ='data Prognosa rutin'!V9 -> 0.80535321
D10: 3 | E10: Akomodasi, Peralatan, dan Perlengkapan Kapal | F10: 294773975 | G10: =[9]MOINIT!$E$58 -> 3011000 | H10: =[10]MOINIT!$E$63 -> 9833000 | I10: =[5]MOINIT!$E$58 -> 6648000 | J10: =[11]MOINIT!$E$58 -> 100533000 | K10: =[6]MOINIT!$E$58 -> 40904920 | L10: =[12]MOINIT!$E$60 -> 3700000 | M10: =[7]MOINIT!E62 -> 15875000 | N10: =SUM(G10:M10) -> 180504920 | O10: ='[13]Hutang 2022'!$J$23 -> 27500000 | Q10: ='[13]Outstanding V1 (SPI)'!$E$32 -> 67900000 | R10: ='[13]Hutang 2022'!$J$24 -> 133463000 | S10: ='[13]Hutang 2022'!$J$26 -> 87418050 | T10: =SUM(O10:S10) -> 316281050 | U10: =T10+N10 -> 496785970 | V10: =U10/F10 -> 1.6853115 | AE10: =[8]Prognosa!G11 -> 177514920 | AF10: =AE10-N10 -> -2990000 | AG10: -68111800 | AP10: ='data Prognosa rutin'!U10 -> 3.0033741e+08 | AQ10: ='data Prognosa rutin'!V10 -> 1.0188736
D11: 4 | E11: Permesinan dan Kelistrikan Kapal | F11: 306018000 | G11: =[9]MOINIT!$E$59 -> 2413000 | H11: =[10]MOINIT!$E$64 -> 6760500 | I11: =[5]MOINIT!$E$59 -> 126616078 | J11: =[11]MOINIT!$E$59 -> 2870000 | K11: =[6]MOINIT!$E$59 -> 5151000 | L11: =[12]MOINIT!$E$61 -> 14980000 | M11: =[7]MOINIT!E63 -> 12375000 | N11: =SUM(G11:M11) -> 171165578 | O11: 43570000 | P11: ='[13]Outstanding V1 (SPI)'!$E$17+'[13]Hutang 2022'!$J$55 -> 35486000 | Q11: ='[13]Outstanding V1 (SPI)'!$E$15+'[13]Hutang 2022'!$J$40 -> 23200000 | R11: ='[13]Outstanding V1 (SPI)'!$E$14 -> 27275000 | S11: ='[13]Outstanding V1 (SPI)'!$E$23 -> 20560400 | T11: =SUM(O11:S11) -> 150091400 | U11: =T11+N11 -> 321256978 | V11: =U11/F11 -> 1.0497977 | AE11: =[8]Prognosa!G12 -> 179754078 | AF11: =AE11-N11 -> 8588500 | AG11: 68812630 | AP11: ='data Prognosa rutin'!U11 -> 307261578 | AQ11: ='data Prognosa rutin'!V11 -> 1.0040637
D12: 5 | E12: Mobilisasi Dlm rangka Docking | F12: 149477700 | L12: =[12]MOINIT!$E$51 -> 167600000 | M12: =[7]MOINIT!$E$52 -> 18436000 | N12: =SUM(G12:M12) -> 186036000 | T12: =SUM(O12:S12) -> 0 | U12: =T12+N12 -> 186036000 | V12: =U12/F12 -> 1.2445736 | AE12: =[8]Prognosa!G13 -> 186036000 | AF12: =AE12-N12 -> 0 | AG12: 0 | AP12: ='data Prognosa rutin'!U12 -> 186036000 | AQ12: ='data Prognosa rutin'!V12 -> 1.2445736
E13: Jumlah | F13: =SUM(F8:F12) -> 2.005882e+09 | G13: =SUM(G8:G12) -> 5424000 | H13: =SUM(H8:H12) -> 16593500 | I13: =SUM(I8:I12) -> 149164078 | J13: =SUM(J8:J12) -> 103403000 | K13: =SUM(K8:K12) -> 69265920 | L13: =SUM(L8:L12) -> 186280000 | M13: =SUM(M8:M12) -> 400032500 | ... U13: =SUM(U8:U12) -> 1.5287211e+09 | V13: =U13/F13 -> 0.76211916 | AE13: =SUM(AE8:AE12) -> 1414951828 | AF13: =SUM(AF8:AF12) -> 484788830 | AG13: 64616200 | AP13: =SUM(AP8:AP12) -> 1.7739675e+09 | AQ13: =AP13/AA13 -> #DIV/0!
B15: 2 | C15: KMP. TUNA TOMINI | D15: 1 | E15: Bahan Pelumas | F15: =[2]REKAP!$F$18 -> 2.6134556e+08 | I15: ='[5]TUNA TOMINI'!$E$52 -> 32284260 | K15: ='[6]TUNA TOMINI'!$E$52 -> 39510000 | N15: =SUM(G15:M15) -> 71794260 | O15: =F15/12 -> 21778796 | P15: =O15 -> 21778796 | Q15: =P15 -> 21778796 | R15: =Q15 -> 21778796 | S15: =R15 -> 21778796 | T15: =SUM(O15:S15) -> 1.0889398e+08 | U15: =T15+N15 -> 1.8068824e+08 | V15: =U15/F15 -> 0.69137675 | AE15: =[8]Prognosa!G16 -> 94192480 | AF15: =AE15-N15 -> 22398220 | AG15: -9500390 | AP15: ='data Prognosa rutin'!U15 -> 2.0308646e+08 | AQ15: ='data Prognosa rutin'!V15 -> 0.77708022
D16: 2 | E16: Kapal RO-RO/Penyeberangan | F16: =908852460 -> 908852460 | K16: ='[6]TUNA TOMINI'!E60 -> 375140000 | L16: ='[12]TUNA TOMINI'!$E$61 -> 67400000 | N16: =SUM(G16:M16) -> 442540000 | O16: ='[13]Hutang 2022'!$J$10 -> 258001318 | P16: ='Rekap Pembayaran'!F53 -> 684198221 | Q16: ='Rekap Pembayaran'!F54+'[13]Hutang 2022'!$J$11 -> 48305367 | R16: 23400000 | S16: 75890000 | T16: =SUM(O16:S16) -> 1089794906 | U16: =T16+N16 -> 1532334906 | V16: =U16/F16 -> 1.6860106 | AE16: =[8]Prognosa!G17 -> 1661115776 | AF16: =AE16-N16 -> 1218575776 | AG16: 724034906 | AP16: ='data Prognosa rutin'!U16 -> 1661115776 | AQ16: ='data Prognosa rutin'!V16 -> 1.8277068
D17: 3 | E17: Akomodasi, Peralatan, dan Perlengkapan Kapal | F17: =278355450 -> 278355450 | G17: ='[9]TUNA TOMINI'!$E$62 -> 19637750 | H17: ='[14]TUNA TOMINI'!$E$63 -> 6706000 | I17: ='[5]TUNA TOMINI'!$E$61 -> 21571000 | J17: ='[11]TUNA TOMINI'!$E$61 -> 2219000 | K17: ='[6]TUNA TOMINI'!E61 -> 110510000 | L17: ='[12]TUNA TOMINI'!$E$62 -> 22944000 | M17: ='[15]TUNA TOMINI'!$E$62 -> 23780000 | N17: =SUM(G17:M17) -> 207367750 | O17: 15750000 | P17: 57500000 | Q17: ='[13]Hutang 2022'!$J$21 -> 54556639 | R17: ='[13]Outstanding V1 (SPI)'!$E$8+'[13]Outstanding V1 (SPI)'!$E$29 -> 49260000 | S17: ='[13]Hutang 2022'!$J$28 -> 58030800 | T17: =SUM(O17:S17) -> 2.3509744e+08 | U17: =T17+N17 -> 4.4246519e+08 | V17: =U17/F17 -> 1.589569 | AE17: =[8]Prognosa!G18 -> 315266188 | AF17: =AE17-N17 -> 107898438 | AG17: 155929758 | AP17: ='data Prognosa rutin'!U17 -> 4.3124763e+08 | AQ17: ='data Prognosa rutin'!V17 -> 1.5492696
D18: 4 | E18: Permesinan dan Kelistrikan Kapal | F18: =243024000 -> 243024000 | G18: ='[9]TUNA TOMINI'!$E$63 -> 2459000 | H18: ='[14]TUNA TOMINI'!$E$64 -> 6848000 | I18: ='[5]TUNA TOMINI'!$E$62 -> 7881000 | J18: ='[11]TUNA TOMINI'!$E$62 -> 14148200 | K18: ='[6]TUNA TOMINI'!E62 -> 72743000 | M18: ='[15]TUNA TOMINI'!$E$63 -> 94947500 | N18: =SUM(G18:M18) -> 199026700 | O18: ='[13]Non Outstanding (Belum Fidias)'!$E$17 -> 24901000 | P18: ='[13]Non Outstanding (Belum Fidias)'!$E$25 -> 48160915 | Q18: ='[13]Hutang 2022'!$J$45+'[13]Hutang 2022'!$J$46 -> 54390000 | R18: ='[13]Outstanding V1 (SPI)'!$E$21+'[13]Hutang 2022'!$J$42+'[13]Hutang 2022'!$J$44 -> 112998870 | S18: ='[13]Outstanding V1 (SPI)'!$E$20+'[13]Hutang 2022'!$J$43 -> 36089000 | T18: =SUM(O18:S18) -> 276539785 | U18: =T18+N18 -> 475566485 | V18: =U18/F18 -> 1.9568705 | AE18: =[8]Prognosa!G19 -> 220917700 | AF18: =AE18-N18 -> 21891000 | AG18: 15608492 | AP18: ='data Prognosa rutin'!U18 -> 322177700 | AQ18: ='data Prognosa rutin'!V18 -> 1.3257032
D19: 5 | E19: Mobilisasi Dlm rangka Docking | F19: =109477700 -> 109477700 | K19: ='[6]TUNA TOMINI'!$E$51 -> 115495500 | N19: =SUM(G19:M19) -> 115495500 | T19: =SUM(O19:S19) -> 0 | U19: =T19+N19 -> 115495500 | V19: =U19/F19 -> 1.0549683 | AE19: =[8]Prognosa!G20 -> 115495500 | AF19: =AE19-N19 -> 0 | AG19: 0 | AP19: ='data Prognosa rutin'!U19 -> 115495500 | AQ19: ='data Prognosa rutin'!V19 -> 1.0549683
E20: Jumlah | F20: =SUM(F15:F19) -> 1.8010552e+09 | G20: =SUM(G15:G19) -> 22096750 | H20: =SUM(H15:H19) -> 13554000 | I20: =SUM(I15:I19) -> 61736260 | J20: =SUM(J15:J19) -> 16367200 | K20: =SUM(K15:K19) -> 713398500 | L20: =SUM(L15:L19) -> 90344000 | M20: =SUM(M15:M19) -> 118727500 | ... U20: =SUM(U15:U19) -> 2.7465503e+09 | V20: =U20/F20 -> 1.5249673 | AE20: =SUM(AE15:AE19) -> 2406987644 | AF20: =SUM(AF15:AF19) -> 1370763434 | AG20: 8.8607277e+08 | AP20: =SUM(AP15:AP19) -> 2.7331231e+09 | AQ20: =AP20/AA20 -> #DIV/0!
B22: 3 | C22: KMP. CENGKIH AFO | D22: 1 | E22: Bahan Pelumas | F22: =[2]REKAP!$F$25 -> 2.6134556e+08 | I22: ='[5]CENGKIH AFO'!$E$53 -> 54894260 | N22: =SUM(G22:M22) -> 54894260 | O22: =F22/12 -> 21778796 | P22: =O22 -> 21778796 | Q22: =P22 -> 21778796 | R22: =Q22 -> 21778796 | S22: =R22 -> 21778796 | T22: =SUM(O22:S22) -> 1.0889398e+08 | U22: =T22+N22 -> 1.6378824e+08 | V22: =U22/F22 -> 0.62671141 | AE22: =[8]Prognosa!G23 -> 69992480 | AF22: =AE22-N22 -> 15098220 | AG22: -24487390 | AP22: ='data Prognosa rutin'!U22 -> 1.7888646e+08 | AQ22: ='data Prognosa rutin'!V22 -> 0.68448251
D23: 2 | E23: Kapal RO-RO/Penyeberangan | F23: 849098940 | H23: ='[16]CENGKIH AFO'!$E$62 -> 205305375 | I23: ='[5]CENGKIH AFO'!E60 -> 349510000 | K23: ='[6]CENGKIH AFO'!$E$60 -> 6240000 | N23: =SUM(G23:M23) -> 561055375 | O23: ='Rekap Pembayaran'!F25 -> 618055064 | P23: ='Rekap Pembayaran'!F26 -> 25390140 | Q23: 176875535 | T23: =SUM(O23:S23) -> 820320739 | U23: =T23+N23 -> 1381376114 | V23: =U23/F23 -> 1.626873 | AE23: =[8]Prognosa!G24 -> 1838757695 | AF23: =AE23-N23 -> 1277702320 | AG23: 1231310195 | AP23: ='data Prognosa rutin'!U23 -> 1838757695 | AQ23: ='data Prognosa rutin'!V23 -> 2.16554
D24: 3 | E24: Akomodasi, Peralatan, dan Perlengkapan Kapal | F24: 262104333 | G24: ='[9]CENGKIH AFO'!$E$61 -> 8118000 | H24: ='[16]CENGKIH AFO'!$E$63 -> 86898500 | I24: ='[5]CENGKIH AFO'!E61 -> 85021000 | J24: ='[11]CENGKIH AFO'!$E$61 -> 126214750 | K24: ='[6]CENGKIH AFO'!$E$61 -> 2678000 | L24: ='[12]CENGKIH AFO'!$E$61 -> 15075000 | M24: ='[17]CENGKIH AFO'!$E$61 -> 8978000 | N24: =SUM(G24:M24) -> 332983250 | P24: 48500000 | Q24: ='[13]Outstanding V1 (SPI)'!$E$28 -> 20350000 | R24: ='[13]Hutang 2022'!$J$25 -> 47752375 | S24: ='[13]Hutang 2022'!$J$31 -> 80780000 | T24: =SUM(O24:S24) -> 197382375 | U24: =T24+N24 -> 530365625 | V24: =U24/F24 -> 2.0234905 | AE24: =[8]Prognosa!G25 -> 249673250 | AF24: =AE24-N24 -> -83310000 | AG24: -44399420 | AP24: ='data Prognosa rutin'!U24 -> 3.5888339e+08 | AQ24: ='data Prognosa rutin'!V24 -> 1.3692387
D25: 4 | E25: Permesinan dan Kelistrikan Kapal | F25: 316778000 | G25: ='[9]CENGKIH AFO'!$E$62 -> 2738000 | H25: ='[16]CENGKIH AFO'!$E$64 -> 73168030 | I25: ='[5]CENGKIH AFO'!E62 -> 24566500 | J25: ='[11]CENGKIH AFO'!$E$62 -> 43291000 | K25: ='[6]CENGKIH AFO'!$E$62 -> 134266900 | M25: ='[17]CENGKIH AFO'!$E$62 -> 6426000 | N25: =SUM(G25:M25) -> 284456430 | O25: ='[13]Hutang 2022'!$J$50 -> 47300000 | P25: ='[13]Hutang 2022'!$J$47+'[13]Hutang 2022'!$J$49 -> 84920000 | Q25: ='[13]Outstanding V1 (SPI)'!$E$16+'[13]Hutang 2022'!$J$39+'[13]Hutang 2022'!$J$48 -> 100895968 | R25: ='[13]Outstanding V1 (SPI)'!$E$22+'[13]Hutang 2022'!$J$51 -> 79871920 | S25: 49870000 | T25: =SUM(O25:S25) -> 362857888 | U25: =T25+N25 -> 647314318 | V25: =U25/F25 -> 2.0434321 | AE25: =[8]Prognosa!G26 -> 297756800 | AF25: =AE25-N25 -> 13300370 | AG25: 58169238 | AP25: ='data Prognosa rutin'!U25 -> 4.2974763e+08 | AQ25: ='data Prognosa rutin'!V25 -> 1.3566208
D26: 5 | E26: Mobilisasi Dlm rangka Docking | F26: 126554300 | I26: ='[5]CENGKIH AFO'!$E$52 -> 186800000 | N26: =SUM(G26:M26) -> 186800000 | T26: =SUM(O26:S26) -> 0 | U26: =T26+N26 -> 186800000 | V26: =U26/F26 -> 1.4760463 | AE26: =[8]Prognosa!G27 -> 186800000 | AF26: =AE26-N26 -> 0 | AG26: 186800000 | AP26: ='data Prognosa rutin'!U26 -> 186800000 | AQ26: ='data Prognosa rutin'!V26 -> 1.4760463
E27: Jumlah | F27: =SUM(F22:F26) -> 1.8158811e+09 | G27: =SUM(G22:G26) -> 10856000 | H27: =SUM(H22:H26) -> 365371905 | I27: =SUM(I22:I26) -> 700791760 | J27: =SUM(J22:J26) -> 169505750 | K27: =SUM(K22:K26) -> 143184900 | L27: =SUM(L22:L26) -> 15075000 | M27: =SUM(M22:M26) -> 15404000 | ... U27: =SUM(U22:U26) -> 2.9096443e+09 | V27: =U27/F27 -> 1.6023319 | AE27: =SUM(AE22:AE26) -> 2642980225 | AF27: =SUM(AF22:AF26) -> 1222790910 | AG27: 1.4073926e+09 | AP27: =SUM(AP22:AP26) -> 2.9930752e+09 | AQ27: =AP27/AA27 -> #DIV/0!
B29: 4 | C29: KMP. TANJUNG API | D29: 1 | E29: Bahan Pelumas | F29: =[2]REKAP!$F$32 -> 2.482551e+08 | I29: ='[5]TANJUNG API'!$E$51 -> 32284260 | K29: ='[6]TANJUNG API'!$E$51 -> 23210000 | M29: ='[18]TANJUNG API'!$E$53 -> 16300000 | N29: =SUM(G29:M29) -> 71794260 | O29: =F29/12 -> 20687925 | P29: =O29 -> 20687925 | Q29: =P29 -> 20687925 | R29: =Q29 -> 20687925 | S29: =R29 -> 20687925 | T29: =SUM(O29:S29) -> 1.0343963e+08 | U29: =T29+N29 -> 1.7523389e+08 | V29: =U29/F29 -> 0.70586217 | AE29: =[8]Prognosa!G30 -> 86892480 | AF29: =AE29-N29 -> 15098220 | AG29: 17065710 | AP29: ='data Prognosa rutin'!U29 -> 1.9033211e+08 | AQ29: ='data Prognosa rutin'!V29 -> 0.76667953
D30: 2 | E30: Kapal RO-RO/Penyeberangan | F30: 790664322 | J30: ='[11]TANJUNG API'!E59 -> 5094100 | L30: =[12]TANJUNG!E61 -> 332914250 | M30: ='[18]TANJUNG API'!E61 -> 62290000 | N30: =SUM(G30:M30) -> 400298350 | O30: ='[13]Hutang 2022'!$J$13 -> 35791950 | P30: 24300000 | Q30: ='Rekap Pembayaran'!F66 -> 420610388 | T30: =SUM(O30:S30) -> 480702338 | U30: =T30+N30 -> 881000688 | V30: =U30/F30 -> 1.1142538 | AE30: =[8]Prognosa!G31 -> 884763187 | AF30: =AE30-N30 -> 484464837 | AG30: 169125652 | AP30: ='data Prognosa rutin'!U30 -> 884763187 | AQ30: ='data Prognosa rutin'!V30 -> 1.1190124
D31: 3 | E31: Akomodasi, Peralatan, dan Perlengkapan Kapal | F31: 224275761 | G31: ='[9]TANJUNG API'!$E$61 -> 9902500 | H31: ='[19]TANJUNG API'!$E$65 -> 10313000 | I31: ='[5]TANJUNG API'!$E$60 -> 2282500 | J31: ='[11]TANJUNG API'!E60 -> 10734600 | K31: ='[6]TANJUNG API'!$E$60 -> 2331000 | L31: =[12]TANJUNG!E62 -> 13912500 | M31: ='[18]TANJUNG API'!E62 -> 127111000 | N31: =SUM(G31:M31) -> 176587100 | P31: ='[13]Outstanding V1 (SPI)'!$E$27 -> 49335000 | Q31: ='Rekap Pembayaran'!F67 -> 25476082 | R31: ='[13]Non Outstanding (Belum Fidias)'!$E$22 -> 20100000 | S31: ='[13]Hutang 2022'!$J$30 -> 137900000 | T31: =SUM(O31:S31) -> 232811082 | U31: =T31+N31 -> 409398182 | V31: =U31/F31 -> 1.8254232 | AE31: =[8]Prognosa!G32 -> 169048600 | AF31: =AE31-N31 -> -7538500 | AG31: -4097895 | AP31: ='data Prognosa rutin'!U31 -> 2.6249683e+08 | AQ31: ='data Prognosa rutin'!V31 -> 1.17042
D32: 4 | E32: Permesinan dan Kelistrikan Kapal | F32: 322506800 | G32: ='[9]TANJUNG API'!$E$62 -> 2725000 | H32: ='[19]TANJUNG API'!$E$66 -> 31656500 | I32: ='[5]TANJUNG API'!$E$61 -> 10460000 | J32: ='[11]TANJUNG API'!E61 -> 3367000 | K32: ='[6]TANJUNG API'!$E$61 -> 20946000 | L32: =[12]TANJUNG!E63 -> 64749362 | M32: ='[18]TANJUNG API'!E63 -> 30321000 | N32: =SUM(G32:M32) -> 164224862 | O32: ='[13]Outstanding V1 (SPI)'!$E$27 -> 49335000 | P32: ='[13]Outstanding V1 (SPI)'!$E$19+'[13]Outstanding V1 (SPI)'!$E$35 -> 48630000 | R32: ='[13]Outstanding V1 (SPI)'!$E$13+'[13]Hutang 2022'!$J$37 -> 34112666 | S32: ='[13]Non Outstanding (Belum Fidias)'!$E$26 -> 53122035 | T32: =SUM(O32:S32) -> 185199701 | U32: =T32+N32 -> 349424563 | V32: =U32/F32 -> 1.0834642 | AE32: =[8]Prognosa!G33 -> 211288362 | AF32: =AE32-N32 -> 47063500 | AG32: -33818077 | AP32: ='data Prognosa rutin'!U32 -> 3.456662e+08 | AQ32: ='data Prognosa rutin'!V32 -> 1.0718106
D33: 5 | E33: Mobilisasi Dlm rangka Docking | F33: 125798050 | L33: =[12]TANJUNG!$E$52 -> 18348000 | N33: =SUM(G33:M33) -> 18348000 | T33: =SUM(O33:S33) -> 0 | U33: =T33+N33 -> 18348000 | V33: =U33/F33 -> 0.14585282 | AE33: =[8]Prognosa!G34 -> 18348000 | AF33: =AE33-N33 -> 0 | AG33: -166800000 | AP33: ='data Prognosa rutin'!U33 -> 18348000 | AQ33: ='data Prognosa rutin'!V33 -> 0.14585282
E34: Jumlah | F34: =SUM(F29:F33) -> 1.7115e+09 | G34: =SUM(G29:G33) -> 12627500 | H34: =SUM(H29:H33) -> 41969500 | I34: =SUM(I29:I33) -> 45026760 | J34: =SUM(J29:J33) -> 19195700 | K34: =SUM(K29:K33) -> 46487000 | L34: =SUM(L29:L33) -> 429924112 | M34: =SUM(M29:M33) -> 236022000 | ... U34: =SUM(U29:U33) -> 1.8334053e+09 | V34: =U34/F34 -> 1.0712272 | AE34: =SUM(AE29:AE33) -> 1370340629 | AF34: =SUM(AF29:AF33) -> 539088057 | AG34: -18524610 | AP34: =SUM(AP29:AP33) -> 1.7016063e+09 | AQ34: =AP34/AA34 -> #DIV/0!
B36: 5 | C36: KMP. TELUK TOLO | D36: 1 | E36: Bahan Pelumas | F36: =[2]REKAP!$F$46 -> 2.6134556e+08 | I36: ='[5]TELUK TOLO'!$E$50 -> 32284260 | K36: ='[6]TELUK TOLO'!$E$50 -> 16300000 | M36: ='[20]TELUK TOLO'!$E$52 -> 39510000 | N36: =SUM(G36:M36) -> 88094260 | O36: =F36/12 -> 21778796 | P36: =O36 -> 21778796 | Q36: =P36 -> 21778796 | R36: =Q36 -> 21778796 | S36: =R36 -> 21778796 | T36: =SUM(O36:S36) -> 1.0889398e+08 | U36: =T36+N36 -> 1.9698824e+08 | V36: =U36/F36 -> 0.75374628 | AE36: =[8]Prognosa!G37 -> 103192480 | AF36: =AE36-N36 -> 15098220 | AG36: 7602610 | AP36: ='data Prognosa rutin'!U36 -> 2.1208646e+08 | AQ36: ='data Prognosa rutin'!V36 -> 0.81151738
D37: 2 | E37: Kapal RO-RO/Penyeberangan | F37: 847824785 | M37: ='[20]TELUK TOLO'!E60 -> 235960203 | N37: =SUM(G37:M37) -> 235960203 | O37: ='[13]Hutang 2022'!$J$9+'[13]Hutang 2022'!$J$12 -> 50239710 | P37: ='[13]Outstanding V1 (SPI)'!$E$4+'[13]Hutang 2022'!$J$14 -> 392773082 | Q37: =(('Rekap Pembayaran'!F91*50%)+'[21]RL Tambahan Docking'!$U$260)*95%+'[13]Hutang 2022'!$J$15 -> 4.3107585e+08 | R37: 24500000 | T37: =SUM(O37:S37) -> 8.9858864e+08 | U37: =T37+N37 -> 1.1345488e+09 | V37: =U37/F37 -> 1.3381879 | AE37: =[8]Prognosa!G38 -> 1252641038 | AF37: =AE37-N37 -> 1016680835 | AG37: 6.3477574e+08 | AP37: ='data Prognosa rutin'!U37 -> 1252641038 | AQ37: ='data Prognosa rutin'!V37 -> 1.4774763
D38: 3 | E38: Akomodasi, Peralatan, dan Perlengkapan Kapal | F38: 315284392 | G38: ='[9]TELUK TOLO'!$E$58 -> 2546000 | H38: ='[22]TELUK TOLO'!$E$63 -> 6881500 | I38: ='[5]TELUK TOLO'!$E$58 -> 2708000 | J38: ='[11]TELUK TOLO'!$E$58 -> 5375500 | K38: ='[6]TELUK TOLO'!$E$58 -> 2681500 | M38: ='[20]TELUK TOLO'!E61 -> 12777500 | N38: =SUM(G38:M38) -> 32970000 | O38: 125700000 | P38: ='[13]Outstanding V1 (SPI)'!$E$7+'[13]Outstanding V1 (SPI)'!$E$9 -> 44020000 | R38: =(('Rekap Pembayaran'!F91*50%)+('[21]RL Tambahan Docking'!$U$260))*5%+'[13]Hutang 2022'!$J$20+'[13]Outstanding V1 (SPI)'!$E$31 -> 1.2774918e+08 | S38: ='[13]Hutang 2022'!$J$27+'[13]Outstanding V1 (SPI)'!$E$30 -> 95052500 | T38: =SUM(O38:S38) -> 3.9252168e+08 | U38: =T38+N38 -> 4.2549168e+08 | V38: =U38/F38 -> 1.3495488 | AE38: =[8]Prognosa!G39 -> 36200500 | AF38: =AE38-N38 -> 3230500 | AG38: -86896650 | AP38: ='data Prognosa rutin'!U38 -> 1.67569e+08 | AQ38: ='data Prognosa rutin'!V38 -> 0.53148523
D39: 4 | E39: Permesinan dan Kelistrikan Kapal | F39: 319556100 | G39: ='[9]TELUK TOLO'!$E$59 -> 2600000 | H39: ='[22]TELUK TOLO'!$E$64 -> 24132200 | I39: ='[5]TELUK TOLO'!$E$59 -> 7210000 | J39: ='[11]TELUK TOLO'!$E$59 -> 6228000 | K39: ='[6]TELUK TOLO'!$E$59 -> 3131000 | L39: ='[12]TELUK TOLO'!$E$59 -> 26265000 | M39: ='[20]TELUK TOLO'!E62 -> 27481000 | N39: =SUM(G39:M39) -> 97047200 | O39: ='[13]Non Outstanding (Belum Fidias)'!$E$18+'[13]Non Outstanding (Belum Fidias)'!$E$19 -> 26265000 | R39: ='[13]Outstanding V1 (SPI)'!$E$12 -> 29220000 | S39: ='[13]Hutang 2022'!$J$36+'[13]Hutang 2022'!$J$38 -> 60310296 | T39: =SUM(O39:S39) -> 115795296 | U39: =T39+N39 -> 212842496 | V39: =U39/F39 -> 0.66605675 | AE39: =[8]Prognosa!G40 -> 80313000 | AF39: =AE39-N39 -> -16734200 | AG39: -35307098 | AP39: ='data Prognosa rutin'!U39 -> 213461375 | AQ39: ='data Prognosa rutin'!V39 -> 0.66799343
D40: 5 | E40: Mobilisasi Dlm rangka Docking | F40: 222399646 | M40: ='[20]TELUK TOLO'!$E$51 -> 116550000 | N40: =SUM(G40:M40) -> 116550000 | T40: =SUM(O40:S40) -> 0 | U40: =T40+N40 -> 116550000 | V40: =U40/F40 -> 0.52405659 | AE40: =[8]Prognosa!G41 -> 116550000 | AF40: =AE40-N40 -> 0 | AG40: 0 | AP40: ='data Prognosa rutin'!U40 -> 116550000 | AQ40: ='data Prognosa rutin'!V40 -> 0.52405659
E41: Jumlah | F41: =SUM(F36:F40) -> 1.9664105e+09 | G41: =SUM(G36:G40) -> 5146000 | H41: =SUM(H36:H40) -> 31013700 | I41: =SUM(I36:I40) -> 42202260 | J41: =SUM(J36:J40) -> 11603500 | K41: =SUM(K36:K40) -> 22112500 | L41: =SUM(L36:L40) -> 26265000 | M41: =SUM(M36:M40) -> 432278703 | ... U41: =SUM(U36:U40) -> 2.0864213e+09 | V41: =U41/F41 -> 1.0610304 | AE41: =SUM(AE36:AE40) -> 1588897018 | AF41: =SUM(AF36:AF40) -> 1018275355 | AG41: 1.6450337e+08 | AP41: =SUM(AP36:AP40) -> 1.9623079e+09 | AQ41: =AP41/AA41 -> #DIV/0!
AF42: =N42-AE42 -> 0 | AG42: 0
B43: 6 | C43: KMP. DOLOSI | D43: 1 | E43: Bahan Pelumas | F43: =[2]REKAP!$F$39 -> 2.4626268e+08 | I43: =[5]DOLOSI!$E$53 -> 15900000 | K43: =[6]DOLOSI!$E$53 -> 16300000 | M43: =[23]DOLOSI!$E$53 -> 23210000 | N43: =SUM(G43:M43) -> 55410000 | O43: =F43/12 -> 20521890 | P43: =O43 -> 20521890 | Q43: =P43 -> 20521890 | R43: =Q43 -> 20521890 | S43: =R43 -> 20521890 | T43: =SUM(O43:S43) -> 1.0260945e+08 | U43: =T43+N43 -> 1.5801945e+08 | V43: =U43/F43 -> 0.64167031 | AE43: =[8]Prognosa!G44 -> 70508220 | AF43: =AE43-N43 -> 15098220 | AG43: 18774450 | AI43: April | AJ43: Mei | AK43: Juni | AL43: Juli | AP43: ='data Prognosa rutin'!U43 -> 1.7311767e+08 | AQ43: ='data Prognosa rutin'!V43 -> 0.70297972
D44: 2 | E44: Kapal RO-RO/Penyeberangan | F44: 876755778 | H44: =[24]DOLOSI!E62 -> 26400000 | I44: =[5]DOLOSI!E60 -> 360403461 | N44: =SUM(G44:M44) -> 386803461 | O44: 25540000 | R44: 23400000 | T44: =SUM(O44:S44) -> 48940000 | U44: =T44+N44 -> 435743461 | V44: =U44/F44 -> 0.49699525 | AE44: =[8]Prognosa!G45 -> 653548850 | AF44: =AE44-N44 -> 266745389 | AG44: -334025189 | AI44: 28744815 | AJ44: 21600000 | AK44: 32400000 | AL44: 45040000 | AM44: =SUM(AI44:AL44) -> 127784815 | AN44: =SUM(AJ44:AL44) -> 99040000 | AP44: ='data Prognosa rutin'!U44 -> 653548850 | AQ44: ='data Prognosa rutin'!V44 -> 0.74541721
D45: 3 | E45: Akomodasi, Peralatan, dan Perlengkapan Kapal | F45: 299803810 | G45: =[9]DOLOSI!$E$61 -> 3105500 | H45: =[24]DOLOSI!E63 -> 15822500 | I45: =[5]DOLOSI!E61 -> 121596250 | J45: =[11]DOLOSI!$E$61 -> 62191500 | K45: =[6]DOLOSI!$E$61 -> 3352500 | M45: =[23]DOLOSI!$E$62 -> 7376500 | N45: =SUM(G45:M45) -> 213444750 | O45: ='[13]Non Outstanding (Belum Fidias)'!$E$10+'[13]Non Outstanding (Belum Fidias)'!$E$11 -> 15750000 | P45: ='[13]Hutang 2022'!$J$22 -> 54062113 | S45: ='[13]Hutang 2022'!$J$29 -> 99090000 | T45: =SUM(O45:S45) -> 168902113 | U45: =T45+N45 -> 382346863 | V45: =U45/F45 -> 1.2753236 | AE45: =[8]Prognosa!G46 -> 213177250 | AF45: =AE45-N45 -> -267500 | AG45: -28336365 | AI45: 0 | AJ45: 0 | AK45: 0 | AL45: 0 | AM45: =SUM(AI45:AL45) -> 0 | AP45: ='data Prognosa rutin'!U45 -> 3.380955e+08 | AQ45: ='data Prognosa rutin'!V45 -> 1.1277225
D46: 4 | E46: Permesinan dan Kelistrikan Kapal | F46: 338927600 | G46: =[9]DOLOSI!$E$62 -> 2570000 | H46: =[24]DOLOSI!E64 -> 82247200 | I46: =[5]DOLOSI!E62 -> 89905000 | J46: =[11]DOLOSI!$E$62 -> 1857000 | K46: =[6]DOLOSI!$E$62 -> 3168000 | L46: =[12]DOLOSI!$E$63 -> 17500000 | M46: =[23]DOLOSI!$E$63 -> 19687500 | N46: =SUM(G46:M46) -> 216934700 | O46: ='[13]Non Outstanding (Belum Fidias)'!$E$14+'[13]Non Outstanding (Belum Fidias)'!$E$15+'[13]Non Outstanding (Belum Fidias)'!$E$16+'[13]Outstanding V1 (SPI)'!$E$36 -> 88056265 | P46: ='[13]Outstanding V1 (SPI)'!$E$18+'[13]Hutang 2022'!$J$54 -> 40526200 | Q46: ='[13]Hutang 2022'!$J$41+'[13]Hutang 2022'!$J$52 -> 75459000 | R46: ='[13]Outstanding V1 (SPI)'!$E$24+'[13]Hutang 2022'!$J$53 -> 51170000 | S46: 43500000 | T46: =SUM(O46:S46) -> 298711465 | U46: =T46+N46 -> 515646165 | V46: =U46/F46 -> 1.5214051 | AE46: =[8]Prognosa!G47 -> 232968700 | AF46: =AE46-N46 -> 16034000 | AG46: -2.043264e+08 | AI46: 15583450 | AJ46: 4572000 | AK46: 65747000 | AL46: 37969019 | AM46: =SUM(AI46:AL46) -> 1.2387147e+08 | AN46: =SUM(AJ46:AL46) -> 1.0828802e+08 | AP46: ='data Prognosa rutin'!U46 -> 3.7418853e+08 | AQ46: ='data Prognosa rutin'!V46 -> 1.1040368
D47: 5 | E47: Mobilisasi Dlm rangka Docking | F47: 189877700 | G47: 127080222 | N47: =SUM(G47:M47) -> 127080222 | T47: =SUM(O47:S47) -> 0 | U47: =T47+N47 -> 127080222 | V47: =U47/F47 -> 0.66927407 | AE47: =[8]Prognosa!G48 -> 20548000 | AF47: =AE47-N47 -> -106532222 | AG47: -394148000 | AI47: 68002600 | AJ47: 32028000 | AK47: 22585500 | AL47: 73692000 | AM47: =SUM(AI47:AL47) -> 196308100 | AN47: =SUM(AJ47:AL47) -> 128305500 | AP47: ='data Prognosa rutin'!U47 -> 20548000 | AQ47: ='data Prognosa rutin'!V47 -> 0.10821703
...

Sheet data Prognosa rutin real
B2: PT. ASDP INDONESIA FERRY (PERSERO)
B3: TABEL REALISASI BIAYA PERAWATAN KAPAL CABANG TERNATE TAHUN 2025
G5: REALISASI BIAYA JANUARI S/D SEPT 2025 | Q5: ESTIMATE OKT S/D DES 2025
B6: NO | C6: NAMA KAPAL | D6: JENIS BIAYA PEMELIHARAAN | F6: RKA 2025 | G6: JANUARI | H6: FEBRUARI | I6: MARET | J6: APRIL | K6: MEI | L6: JUNI | M6: JULI | N6: AGUS | O6: SEPT | P6: TOTAL REALISASI BIAYA JAN S/D SEPT 2025 | Q6: OKT | R6: NOP | S6: DES | T6: TOTAL ESTIMATE AGUS S/D DES 2025 | U6: PROGNOSA 2025 | V6: PRESENTASE PENYERAPAN RKAC | AE6: REALISASI BIAYA
P7: =SUM(G7:O7) -> 0 | T7: =SUM(N7:S7) -> 0
B8: 1 | C8: KMP. ARIWANGAN | D8: 1 | E8: Bahan Pelumas | F8: 1.0863056e+08 | H8: 6052640 | I8: 6052640 | J8: 6052640 | K8: 6052640 | L8: 6052640 | M8: 12105280 | N8: 6052640 | O8: 6052640 | P8: =SUM(G8:O8) -> 54473760 | Q8: 12589795 | R8: 12589795 | S8: 12589795 | T8: =SUM(Q8:S8) -> 37769385 | U8: =P8+T8 -> 92243145 | V8: =U8/F8 -> 0.84914542 | AE8: =[8]Prognosa!G9 -> 70508220 | AF8: =AE8-#REF! -> #REF! | AG8: 18774450
D9: 2 | E9: Pengangkutan Pelumas | F9: 0 | G9: 0 | P9: =SUM(G9:O9) -> 0 | Q9: 0 | R9: 0 | S9: 0 | T9: =SUM(Q9:S9) -> 0 | U9: =P9+T9 -> 0 | V9: =U9/F9 -> #DIV/0!
D10: 3 | E10: Kapal RO-RO/Penyeberangan | F10: 663765057 | L10: 201057100 | M10: 141414390 | P10: =SUM(G10:O10) -> 342471490 | T10: =SUM(Q10:S10) -> 0 | U10: =P10+T10 -> 342471490 | V10: =U10/F10 -> 0.51595288 | AE10: =[8]Prognosa!G10 -> 801138610 | AF10: =AE10-#REF! -> #REF! | AG10: 45140920
D11: 4 | E11: Akomodasi, Peralatan, dan Perlengkapan Kapal | F11: 3.3276005e+08 | H11: 2530000 | I11: 3385000 | J11: 0 | K11: 81360000 | L11: 125328000 | M11: 30443000 | O11: 4030000 | P11: =SUM(G11:O11) -> 247076000 | Q11: 17045669 | R11: 17045669 | S11: 17045669 | T11: =SUM(Q11:S11) -> 51137007 | U11: =P11+T11 -> 298213007 | V11: =U11/F11 -> 0.89618032 | AE11: =[8]Prognosa!G11 -> 177514920 | AF11: =AE11-#REF! -> #REF! | AG11: -68111800
D12: 5 | E12: Permesinan dan Kelistrikan Kapal | F12: 3.8251609e+08 | H12: 1595000 | I12: 30316250 | J12: 0 | K12: 4606651 | L12: 34105448 | M12: 4661000 | O12: 12370000 | P12: =SUM(G12:O12) -> 87654349 | Q12: 58374029 | R12: 58374029 | S12: 58374029 | T12: =SUM(Q12:S12) -> 175122087 | U12: =P12+T12 -> 262776436 | V12: =U12/F12 -> 0.68696833 | AE12: =[8]Prognosa!G12 -> 179754078 | AF12: =AE12-#REF! -> #REF! | AG12: 68812630
D13: 6 | E13: Mobilisasi Dlm rangka Docking | F13: 97496738 | L13: 6052640 | M13: 73125000 | P13: =SUM(G13:O13) -> 79177640 | T13: =SUM(Q13:S13) -> 0 | U13: =P13+T13 -> 79177640 | V13: =U13/F13 -> 0.81210553 | AE13: =[8]Prognosa!G13 -> 186036000 | AF13: =AE13-#REF! -> #REF! | AG13: 0
D14: 7 | E14: Sertifikasi Alat Produksi dalam Rangka Docking | F14: 88000000 | L14: 23000000 | P14: =SUM(G14:O14) -> 23000000 | Q14: 12350000 | R14: 12350000 | S14: 12350000 | T14: =SUM(Q14:S14) -> 37050000 | U14: =P14+T14 -> 60050000 | V14: =U14/F14 -> 0.68238636
D15: 8 | E15: Fumigasi | F15: 14200000 | O15: =SUM(I15:N15) -> 0 | P15: =SUM(G15:O15) -> 0 | Q15: =SUM(J15:O15) -> 0 | R15: =SUM(K15:Q15) -> 0 | S15: =SUM(L15:R15) -> 0 | T15: =SUM(N15:S15) -> 0 | U15: =P15+T15 -> 0 | V15: =U15/F15 -> 0
E16: Jumlah | F16: =SUM(F8:F15) -> 1.6873685e+09 | G16: =SUM(G8:G15) -> 0 | H16: =SUM(H8:H15) -> 10177640 | I16: =SUM(I8:I15) -> 39753890 | J16: =SUM(J8:J15) -> 6052640 | K16: =SUM(K8:K15) -> 92019291 | L16: =SUM(L8:L15) -> 395595828 | M16: =SUM(M8:M15) -> 261748670 | ... O16: =SUM(O8:O15) -> 22452640 | P16: =SUM(P7:P15) -> 833853239 | Q16: =SUM(Q8:Q15) -> 100359493 | R16: =SUM(R8:R15) -> 100359493 | S16: =SUM(S8:S15) -> 100359493 | T16: =SUM(T8:T15) -> 301078479 | U16: =SUM(U8:U15) -> 1134931718 | V16: =U16/F16 -> 0.67260455 | AE16: =SUM(AE8:AE13) -> 1414951828 | AF16: =SUM(AF8:AF13) -> #REF! | AG16: 64616200
P17: =SUM(G17:O17) -> 0 | T17: =SUM(N17:S17) -> 0 | U17: =P17+T17 -> 0
B18: 2 | C18: KMP. BARONANG | D18: 1 | E18: Bahan Pelumas | F18: 1.8413992e+08 | H18: 12105280 | I18: 12105280 | J18: 12105280 | K18: 12105280 | N18: 12105280 | O18: 12105280 | P18: =SUM(G18:O18) -> 72631680 | Q18: 25786572 | R18: 12105280 | S18: 25786572 | T18: =SUM(Q18:S18) -> 63678424 | U18: =P18+T18 -> 136310104 | V18: =U18/F18 -> 0.74025285 | AE18: =[8]Prognosa!G16 -> 94192480 | AF18: =AE18-#REF! -> #REF! | AG18: -9500390
D19: 2 | E19: Pengangkutan Pelumas | P19: =SUM(G19:O19) -> 0 | T19: =SUM(Q19:S19) -> 0 | U19: =P19+T19 -> 0 | V19: =U19/F19 -> #DIV/0! | AE19: =[8]Prognosa!G17 -> 1661115776 | AF19: =AE19-#REF! -> #REF! | AG19: 724034906
D20: 3 | E20: Kapal RO-RO/Penyeberangan | F20: 1059966677 | M20: 389949175 | P20: =SUM(G20:O20) -> 389949175 | T20: =SUM(Q20:S20) -> 0 | U20: =P20+T20 -> 389949175 | V20: =U20/F20 -> 0.36788815 | AE20: =[8]Prognosa!G18 -> 315266188 | AF20: =AE20-#REF! -> #REF! | AG20: 155929758
D21: 4 | E21: Akomodasi, Peralatan, dan Perlengkapan Kapal | F21: 473299060 | H21: 16740500 | I21: 4472000 | K21: 4321000 | L21: 5927000 | M21: 22823700 | N21: 12030000 | O21: 6645000 | P21: =SUM(G21:O21) -> 72959200 | Q21: 79612823 | R21: 79612823 | S21: 79612823 | T21: =SUM(Q21:S21) -> 238838469 | U21: =P21+T21 -> 311797669 | V21: =U21/F21 -> 0.65877517 | AE21: =[8]Prognosa!G19 -> 220917700 | AF21: =AE21-#REF! -> #REF! | AG21: 15608492
D22: 5 | E22: Permesinan dan Kelistrikan Kapal | F22: 461609908 | H22: 51347000 | I22: 6506000 | K22: 1103000 | L22: 29973154 | M22: 60722400 | N22: 12346000 | O22: 14877000 | P22: =SUM(G22:O22) -> 176874554 | Q22: 59272087 | R22: 59272087 | S22: 59272087 | T22: =SUM(Q22:S22) -> 177816261 | U22: =P22+T22 -> 354690815 | V22: =U22/F22 -> 0.76837782
D23: 6 | E23: Mobilisasi Dlm rangka Docking | F23: 1.3384755e+08 | P23: =SUM(G23:O23) -> 0 | Q23: 25431035 | R23: 25431035 | S23: 25431035 | T23: =SUM(Q23:S23) -> 76293105 | U23: =P23+T23 -> 76293105 | V23: =U23/F23 -> 0.56999999
D24: 7 | E24: Sertifikasi Alat Produksi dalam Rangka Docking | F24: 94050000 | L24: 37101750 | M24: 21274368 | P24: =SUM(G24:O24) -> 58376118 | Q24: 28000000 | T24: =SUM(Q24:S24) -> 28000000 | U24: =P24+T24 -> 86376118 | V24: =U24/F24 -> 0.91840636
D25: 8 | E25: Fumigasi | F25: 24500000 | P25: =SUM(G25:O25) -> 0 | T25: =SUM(N25:S25) -> 0 | U25: =P25+T25 -> 0 | V25: =U25/F25 -> 0 | AE25: =[8]Prognosa!G20 -> 115495500 | AF25: =AE25-#REF! -> #REF! | AG25: 0
E26: Jumlah | F26: =SUM(F18:F25) -> 2.4314131e+09 | G26: =SUM(G18:G25) -> 0 | H26: =SUM(H18:H25) -> 80192780 | I26: =SUM(I18:I25) -> 23083280 | J26: =SUM(J18:J25) -> 12105280 | K26: =SUM(K18:K25) -> 17529280 | L26: =SUM(L18:L25) -> 73001904 | M26: =SUM(M18:M25) -> 494769643 | ... O26: =SUM(O18:O25) -> 33627280 | P26: =SUM(P17:P25) -> 770790727 | Q26: =SUM(Q18:Q25) -> 218102517 | R26: =SUM(R18:R25) -> 176421225 | S26: =SUM(S18:S25) -> 190102517 | T26: =SUM(T18:T25) -> 584626259 | U26: =SUM(U18:U25) -> 1355416986 | V26: =U26/F26 -> 0.55746059 | AE26: =SUM(AE18:AE25) -> 2406987644 | AF26: =SUM(AF18:AF25) -> #REF! | AG26: 8.8607277e+08
P27: =SUM(G27:O27) -> 0 | T27: =SUM(N27:S27) -> 0 | U27: =P27+T27 -> 0
B28: 3 | C28: KMP. BOBARA | D28: 1 | E28: Bahan Pelumas | F28: 184892532 | H28: 6052640 | I28: 6052640 | J28: 12105280 | K28: 6052640 | L28: 12105280 | M28: 18838300 | N28: 12105280 | O28: 12105280 | P28: =SUM(G28:O28) -> 85417340 | Q28: 15786573 | R28: 15786573 | S28: 15786573 | T28: =SUM(Q28:S28) -> 47359718 | U28: =P28+T28 -> 1.3277706e+08 | V28: =U28/F28 -> 0.71813099 | AE28: =[8]Prognosa!G23 -> 69992480 | AF28: =AE28-#REF! -> #REF! | AG28: -24487390
D29: 2 | E29: Pengangkutan Pelumas | P29: =SUM(G29:O29) -> 0 | T29: =SUM(Q29:S29) -> 0 | U29: =P29+T29 -> 0 | V29: =U29/F29 -> #DIV/0!
D30: 3 | E30: Kapal RO-RO/Penyeberangan | F30: 972242586 | H30: 52284055 | P30: =SUM(G30:O30) -> 52284055 | Q30: 919950000 | T30: =SUM(Q30:S30) -> 919950000 | U30: =P30+T30 -> 972234055 | V30: =U30/F30 -> 0.99999123
D31: 4 | E31: Akomodasi, Peralatan, dan Perlengkapan Kapal | F31: 3.8805439e+08 | G31: 0 | H31: 2549000 | I31: 4565000 | J31: 0 | K31: 2604000 | L31: 4790000 | M31: 9936000 | N31: 7945000 | O31: 9042000 | P31: =SUM(G31:O31) -> 41431000 | Q31: =245159100.9+25000000 -> 2.701591e+08 | R31: 29612823 | S31: 29612823 | T31: =SUM(Q31:S31) -> 3.2938475e+08 | U31: =P31+T31 -> 3.7081575e+08 | V31: =U31/F31 -> 0.95557673
D32: 5 | E32: Permesinan dan Kelistrikan Kapal | F32: 433496910 | G32: 12500000 | H32: 25621100 | I32: 16297300 | J32: 0 | K32: 10659625 | L32: 2251000 | M32: 11169400 | N32: 12760000 | O32: 8074000 | P32: =SUM(G32:O32) -> 99332425 | Q32: =317910135.96 -> 3.1791014e+08 | R32: 9272087.3 | S32: 9272087.3 | T32: =SUM(Q32:S32) -> 3.3645431e+08 | U32: =P32+T32 -> 4.3578674e+08 | V32: =U32/F32 -> 1.0052822 | AE32: =[8]Prognosa!G24 -> 1838757695 | AF32: =AE32-#REF! -> #REF! | AG32: 1231310195
D33: 6 | E33: Mobilisasi Dlm rangka Docking | F33: 1.3783177e+08 | K33: 30108750 | P33: =SUM(G33:O33) -> 30108750 | Q33: =F33-K33 -> 1.0772302e+08 | T33: =SUM(Q33:S33) -> 1.0772302e+08 | U33: =P33+T33 -> 1.3783177e+08 | V33: =U33/F33 -> 1 | AE33: =[8]Prognosa!G25 -> 249673250 | AF33: =AE33-#REF! -> #REF! | AG33: -44399420
D34: 7 | E34: Sertifikasi Alat Produksi dalam Rangka Docking | F34: 77550000 | G34: 46065000 | J34: 32345400 | P34: =SUM(G34:O34) -> 78410400 | Q34: 37000000 | T34: =SUM(Q34:S34) -> 37000000 | U34: =P34+T34 -> 115410400 | V34: =U34/F34 -> 1.4882063 | AE34: =[8]Prognosa!G26 -> 297756800 | AF34: =AE34-#REF! -> #REF! | AG34: 58169238
D35: 8 | E35: Fumigasi | F35: 23400000 | P35: =SUM(G35:O35) -> 0 | Q35: =F35 -> 23400000 | T35: =SUM(Q35:S35) -> 23400000 | U35: =P35+T35 -> 23400000 | V35: =U35/F35 -> 1 | AE35: =[8]Prognosa!G27 -> 186800000 | AF35: =AE35-#REF! -> #REF! | AG35: 186800000
E36: Jumlah | F36: =SUM(F28:F35) -> 2.2174682e+09 | G36: =SUM(G28:G35) -> 58565000 | H36: =SUM(H28:H35) -> 86506795 | I36: =SUM(I28:I35) -> 26914940 | J36: =SUM(J28:J35) -> 44450680 | K36: =SUM(K28:K35) -> 49425015 | L36: =SUM(L28:L35) -> 19146280 | M36: =SUM(M28:M35) -> 39943700 | ... O36: =SUM(O28:O35) -> 29221280 | P36: =SUM(P27:P35) -> 386983970 | Q36: =SUM(Q28:Q35) -> 1.6919288e+09 | R36: =SUM(R28:R35) -> 54671483 | S36: =SUM(S28:S35) -> 54671483 | T36: =SUM(T28:T35) -> 1.8012718e+09 | U36: =SUM(U28:U35) -> 2.1882558e+09 | V36: =U36/F36 -> 0.98682623 | AE36: =SUM(AE28:AE35) -> 2642980225 | AF36: =SUM(AF28:AF35) -> #REF! | AG36: 1.4073926e+09
P37: =SUM(G37:O37) -> 0 | T37: =SUM(Q37:S37) -> 0 | U37: =P37+T37 -> 0
B38: 4 | C38: KMP. GORANGO | D38: 1 | E38: Bahan Pelumas | F38: 1.7493442e+08 | H38: 6052640 | I38: 6052640 | J38: 18103580 | K38: 6052640 | L38: 6052640 | M38: 24210560 | N38: 12105280 | O38: 12105280 | P38: =SUM(G38:O38) -> 90735260 | Q38: 21681945 | R38: 21681945 | S38: 21681945 | T38: =SUM(Q38:S38) -> 65045835 | U38: =P38+T38 -> 1.5578109e+08 | V38: =U38/F38 -> 0.89051137 | AE38: =[8]Prognosa!G30 -> 86892480 | AF38: =AE38-#REF! -> #REF! | AG38: 17065710
D39: 2 | E39: Pengangkutan Pelumas | F39: 0 | P39: =SUM(G39:O39) -> 0 | T39: =SUM(Q39:S39) -> 0 | U39: =P39+T39 -> 0 | V39: =U39/F39 -> #DIV/0! | AE39: =[8]Prognosa!G31 -> 884763187 | AF39: =AE39-#REF! -> #REF! | AG39: 169125652
D40: 3 | E40: Kapal RO-RO/Penyeberangan | F40: 879493158 | G40: 414417512 | H40: 372975760 | K40: 481583957 | P40: =SUM(G40:O40) -> 1268977229 | T40: =SUM(Q40:S40) -> 0 | U40: =P40+T40 -> 1268977229 | V40: =U40/F40 -> 1.4428506 | AE40: =[8]Prognosa!G32 -> 169048600 | AF40: =AE40-#REF! -> #REF! | AG40: -4097895
D41: 4 | E41: Akomodasi, Peralatan, dan Perlengkapan Kapal | F41: 4.4252615e+08 | H41: 11480000 | I41: 111902000 | J41: 45972700 | K41: 87292000 | L41: 4555000 | M41: 81958500 | N41: 14721000 | O41: 8634000 | P41: =SUM(G41:O41) -> 366515200 | Q41: 14873190 | R41: 14873190 | S41: 14873190 | T41: =SUM(Q41:S41) -> 44619572 | U41: =P41+T41 -> 4.1113477e+08 | V41: =U41/F41 -> 0.92906322
D42: 5 | E42: Permesinan dan Kelistrikan Kapal | F42: 455879420 | H42: 46027860 | I42: 26658750 | J42: 0 | K42: 98599000 | L42: 14171000 | M42: 65463800 | N42: 23007000 | O42: 17243000 | P42: =SUM(G42:O42) -> 291170410 | Q42: 20991802 | R42: 20991802 | S42: 20991802 | T42: =SUM(Q42:S42) -> 62975406 | U42: =P42+T42 -> 354145816 | V42: =U42/F42 -> 0.77684098
...

Sheet Prognosa
B2: PT. ASDP INDONESIA FERRY (PERSERO)
B3: TABEL PENYUSUNAN PROGNOSA RKAC BIAYA PERAWATAN KAPAL CABANG LUWUK TAHUN 2024
B5: NO | C5: NAMA KAPAL | D5: JENIS BIAYA PEMELIHARAAN | F5: RKA 2023 | G5: REALISASI JAN S/D JULI 2023 | H5: ESTIMATE AGUSTUS S/D DES 2023 | I5: PROGNOSA 2023 | J5: DEVIASI PROGNOSA TERHADAP RKAC 2023 | K5: USULAN RKAC 2024 | L5: DEVIASI USULAN RKAC 2024
L6: TERHADAP RKAC 2024 (%) | M6: TERHADAP PROGNOSA
B7: 1 | C7: 2 | D7: 3 | F7: 4 | G7: 5 | H7: 6 | I7: 7 (5 + 6) | J7: 8 (7:4) | K7: 9 | L7: 10 (9:4) | M7: 11 (7:9)
B9: 1 | C9: KMP. MOINIT | D9: 1 | E9: Bahan Pelumas | F9: =[2]REKAP!$F$11 -> 2.6084556e+08 | G9: ='[3]PROGNOSA (2)'!$D$54 -> 70508220 | H9: ='data Prognosa rutin'!T8 -> 1.0868565e+08 | I9: ='data Prognosa rutin'!U8 -> 1.7919387e+08 | J9: =I9/F9 -> 0.68697305 | K9: ='[26]REKAPITULASI KAPAL'!$I$11 -> 2.2353116e+08 | L9: =K9/F9 -> 0.85694831 | M9: =K9/I9 -> 1.2474264
D10: 2 | E10: Kapal RO-RO/Penyeberangan | F10: 994766768 | G10: ='[3]PROGNOSA (2)'!$D$55 -> 801138610 | H10: ='data Prognosa rutin'!T9 -> 0 | I10: ='data Prognosa rutin'!U9 -> 801138610 | J10: =I10/F10 -> 0.80535321 | K10: ='[26]REKAPITULASI KAPAL'!$I$14 -> 7.6053883e+08 | L10: =K10/F10 -> 0.76453985 | M10: =K10/I10 -> 0.94932241
D11: 3 | E11: Akomodasi, Peralatan, dan Perlengkapan Kapal | F11: 294773975 | G11: ='[3]PROGNOSA (2)'!$D$56 -> 177514920 | H11: ='data Prognosa rutin'!T10 -> 1.2282249e+08 | I11: ='data Prognosa rutin'!U10 -> 3.0033741e+08 | J11: =I11/F11 -> 1.0188736 | K11: ='[26]REKAPITULASI KAPAL'!$I$20 -> 435264650 | L11: =K11/F11 -> 1.4766047 | M11: =K11/I11 -> 1.4492522
D12: 4 | E12: Permesinan dan Kelistrikan Kapal | F12: 306018000 | G12: ='[3]PROGNOSA (2)'!$D$57 -> 179754078 | H12: ='data Prognosa rutin'!T11 -> 127507500 | I12: ='data Prognosa rutin'!U11 -> 307261578 | J12: =I12/F12 -> 1.0040637 | K12: ='[26]REKAPITULASI KAPAL'!$I$27 -> 443685430 | L12: =K12/F12 -> 1.4498671 | M12: =K12/I12 -> 1.4439991
D13: 5 | E13: Mobilisasi Dlm rangka Docking | F13: 149477700 | G13: ='[3]PROGNOSA (2)'!$D$53 -> 186036000 | H13: ='data Prognosa rutin'!T12 -> 0 | I13: ='data Prognosa rutin'!U12 -> 186036000 | J13: =I13/F13 -> 1.2445736 | K13: ='[26]REKAPITULASI KAPAL'!$I$33 -> 186400000 | L13: =K13/F13 -> 1.2470088 | M13: =K13/I13 -> 1.0019566 | N13: =#REF!/G13 -> #REF!
E14: Jumlah | F14: =SUM(F9:F13) -> 2.005882e+09 | G14: =SUM(G9:G13) -> 1414951828 | H14: =SUM(H9:H13) -> 3.5901564e+08 | I14: =SUM(I9:I13) -> 1.7739675e+09 | J14: =I14/G14 -> 1.2537299 | K14: =SUM(K9:K13) -> 2.0494201e+09 | L14: =K14/F14 -> 1.0217052 | M14: =K14/I14 -> 1.1552749
B16: 2 | C16: KMP. TUNA TOMINI | D16: 1 | E16: Bahan Pelumas | F16: =[2]REKAP!$F$18 -> 2.6134556e+08 | G16: ='[3]PROGNOSA (2)'!D5 -> 94192480 | H16: ='data Prognosa rutin'!T15 -> 1.0889398e+08 | I16: ='data Prognosa rutin'!U15 -> 2.0308646e+08 | J16: =I16/F16 -> 0.77708022 | K16: ='[26]REKAPITULASI KAPAL'!$G$11 -> 2.0458355e+08 | L16: =K16/F16 -> 0.7828086 | M16: =K16/I16 -> 1.0073717
D17: 2 | E17: Kapal RO-RO/Penyeberangan | F17: =908852460 -> 908852460 | G17: ='[3]PROGNOSA (2)'!D6 -> 1661115776 | H17: ='data Prognosa rutin'!T16 -> 0 | I17: ='data Prognosa rutin'!U16 -> 1661115776 | J17: =I17/F17 -> 1.8277068 | K17: ='[26]REKAPITULASI KAPAL'!$G$14 -> 822284767 | L17: =K17/F17 -> 0.90475055 | M17: =K17/I17 -> 0.49501954
D18: 3 | E18: Akomodasi, Peralatan, dan Perlengkapan Kapal | F18: =278355450 -> 278355450 | G18: ='[3]PROGNOSA (2)'!D7 -> 315266188 | H18: ='data Prognosa rutin'!T17 -> 1.1598144e+08 | I18: ='data Prognosa rutin'!U17 -> 4.3124763e+08 | J18: =I18/F18 -> 1.5492696 | K18: ='[26]REKAPITULASI KAPAL'!$G$20 -> 496122900 | L18: =K18/F18 -> 1.7823359 | M18: =K18/I18 -> 1.1504362
D19: 4 | E19: Permesinan dan Kelistrikan Kapal | F19: =243024000 -> 243024000 | G19: ='[3]PROGNOSA (2)'!D8 -> 220917700 | H19: ='data Prognosa rutin'!T18 -> 101260000 | I19: ='data Prognosa rutin'!U18 -> 322177700 | J19: =I19/F19 -> 1.3257032 | K19: ='[26]REKAPITULASI KAPAL'!$G$27 -> 478047520 | L19: =K19/F19 -> 1.9670795 | M19: =K19/I19 -> 1.4838008
D20: 5 | E20: Mobilisasi Dlm rangka Docking | F20: =109477700 -> 109477700 | G20: ='[3]PROGNOSA (2)'!$D$4 -> 115495500 | H20: ='data Prognosa rutin'!T19 -> 0 | I20: ='data Prognosa rutin'!U19 -> 115495500 | J20: =I20/F20 -> 1.0549683 | K20: ='[26]REKAPITULASI KAPAL'!$G$33 -> 151000000 | L20: =K20/F20 -> 1.3792763 | M20: =K20/I20 -> 1.3074102
E21: Jumlah | F21: =SUM(F16:F20) -> 1.8010552e+09 | G21: =SUM(G16:G20) -> 2406987644 | H21: =SUM(H16:H20) -> 3.2613542e+08 | I21: =SUM(I16:I20) -> 2.7331231e+09 | J21: =I21/G21 -> 1.1354953 | K21: =SUM(K16:K20) -> 2.1520387e+09 | L21: =K21/F21 -> 1.1948766 | M21: =K21/I21 -> 0.78739182
B23: 3 | C23: KMP. CENGKIH AFO | D23: 1 | E23: Bahan Pelumas | F23: =[2]REKAP!$F$25 -> 2.6134556e+08 | G23: ='[3]PROGNOSA (2)'!D29 -> 69992480 | H23: ='data Prognosa rutin'!T22 -> 1.0889398e+08 | I23: ='data Prognosa rutin'!U22 -> 1.7888646e+08 | J23: =I23/F23 -> 0.68448251 | K23: ='[26]REKAPITULASI KAPAL'!$E$11 -> 2.2394111e+08 | L23: =K23/F23 -> 0.85687743 | M23: =K23/I23 -> 1.2518617
D24: 2 | E24: Kapal RO-RO/Penyeberangan | F24: 849098940 | G24: ='[3]PROGNOSA (2)'!D30 -> 1838757695 | H24: ='data Prognosa rutin'!T23 -> 0 | I24: ='data Prognosa rutin'!U23 -> 1838757695 | J24: =I24/F24 -> 2.16554 | K24: ='[26]REKAPITULASI KAPAL'!$E$14 -> 829414900 | L24: =K24/F24 -> 0.97681773 | M24: =K24/I24 -> 0.45107352
D25: 3 | E25: Akomodasi, Peralatan, dan Perlengkapan Kapal | F25: 262104333 | G25: ='[3]PROGNOSA (2)'!D31 -> 249673250 | H25: ='data Prognosa rutin'!T24 -> 1.0921014e+08 | I25: ='data Prognosa rutin'!U24 -> 3.5888339e+08 | J25: =I25/F25 -> 1.3692387 | K25: ='[26]REKAPITULASI KAPAL'!$E$20 -> 507260900 | L25: =K25/F25 -> 1.9353396 | M25: =K25/I25 -> 1.4134421
D26: 4 | E26: Permesinan dan Kelistrikan Kapal | F26: 316778000 | G26: ='[3]PROGNOSA (2)'!D32 -> 297756800 | H26: ='data Prognosa rutin'!T25 -> 1.3199083e+08 | I26: ='data Prognosa rutin'!U25 -> 4.2974763e+08 | J26: =I26/F26 -> 1.3566208 | K26: ='[26]REKAPITULASI KAPAL'!$E$27 -> 4.7731119e+08 | L26: =K26/F26 -> 1.5067687 | M26: =K26/I26 -> 1.1106779
D27: 5 | E27: Mobilisasi Dlm rangka Docking | F27: 126554300 | G27: ='[3]PROGNOSA (2)'!$D$28 -> 186800000 | H27: ='data Prognosa rutin'!T26 -> 0 | I27: ='data Prognosa rutin'!U26 -> 186800000 | J27: =I27/F27 -> 1.4760463 | K27: ='[26]REKAPITULASI KAPAL'!$E$33 -> 189000000 | L27: =K27/F27 -> 1.4934301 | M27: =K27/I27 -> 1.0117773
E28: Jumlah | F28: =SUM(F23:F27) -> 1.8158811e+09 | G28: =SUM(G23:G27) -> 2642980225 | H28: =SUM(H23:H27) -> 3.5009495e+08 | I28: =SUM(I23:I27) -> 2.9930752e+09 | J28: =I28/G28 -> 1.1324622 | K28: =SUM(K23:K27) -> 2.2269281e+09 | L28: =K28/F28 -> 1.2263623 | M28: =K28/I28 -> 0.74402678
B30: 4 | C30: KMP. TANJUNG API | D30: 1 | E30: Bahan Pelumas | F30: =[2]REKAP!$F$32 -> 2.482551e+08 | G30: ='[3]PROGNOSA (2)'!D17 -> 86892480 | H30: ='data Prognosa rutin'!T29 -> 1.0343963e+08 | I30: ='data Prognosa rutin'!U29 -> 1.9033211e+08 | J30: =I30/F30 -> 0.76667953 | K30: ='[26]REKAPITULASI KAPAL'!$H$11 -> 2.1598029e+08 | L30: =K30/F30 -> 0.86999336 | M30: =K30/I30 -> 1.1347549
D31: 2 | E31: Kapal RO-RO/Penyeberangan | F31: 790664322 | G31: ='[3]PROGNOSA (2)'!D18 -> 884763187 | H31: ='data Prognosa rutin'!T30 -> 0 | I31: ='data Prognosa rutin'!U30 -> 884763187 | J31: =I31/F31 -> 1.1190124 | K31: ='[26]REKAPITULASI KAPAL'!$H$14 -> 736184817 | L31: =K31/F31 -> 0.93109654 | M31: =K31/I31 -> 0.8320699
D32: 3 | E32: Akomodasi, Peralatan, dan Perlengkapan Kapal | F32: 224275761 | G32: ='[3]PROGNOSA (2)'!D19 -> 169048600 | H32: ='data Prognosa rutin'!T31 -> 93448234 | I32: ='data Prognosa rutin'!U31 -> 2.6249683e+08 | J32: =I32/F32 -> 1.17042 | K32: ='[26]REKAPITULASI KAPAL'!$H$20 -> 480650200 | L32: =K32/F32 -> 2.1431215 | M32: =K32/I32 -> 1.8310705
D33: 4 | E33: Permesinan dan Kelistrikan Kapal | F33: 322506800 | G33: ='[3]PROGNOSA (2)'!D20 -> 211288362 | H33: ='data Prognosa rutin'!T32 -> 1.3437783e+08 | I33: ='data Prognosa rutin'!U32 -> 3.456662e+08 | J33: =I33/F33 -> 1.0718106 | K33: ='[26]REKAPITULASI KAPAL'!$H$27 -> 450467330 | L33: =K33/F33 -> 1.3967685 | M33: =K33/I33 -> 1.303186
D34: 5 | E34: Mobilisasi Dlm rangka Docking | F34: 125798050 | G34: ='[3]PROGNOSA (2)'!$D$16 -> 18348000 | H34: ='data Prognosa rutin'!T33 -> 0 | I34: ='data Prognosa rutin'!U33 -> 18348000 | J34: =I34/F34 -> 0.14585282 | K34: ='[26]REKAPITULASI KAPAL'!$H$33 -> 1.6270544e+08 | L34: =K34/F34 -> 1.293386 | M34: =K34/I34 -> 8.867748
E35: Jumlah | F35: =SUM(F30:F34) -> 1.7115e+09 | G35: =SUM(G30:G34) -> 1370340629 | H35: =SUM(H30:H34) -> 3.3126569e+08 | I35: =SUM(I30:I34) -> 1.7016063e+09 | J35: =I35/G35 -> 1.2417397 | K35: =SUM(K30:K34) -> 2.0459881e+09 | L35: =K35/F35 -> 1.1954356 | M35: =K35/I35 -> 1.2023863
