Workbook

Sheet Daftar Swakelola
A2: PT. ASDP INDONESIA FERRY (PERSERO) CABANG TERNATE
A4: DAFTAR PEMBAYARAN SWAKELOLA
A5: PEKERJAAN DOCKING KMP. Lema TAHUN 2025
A7: NO. | B7: N A M A | F7: JUMLAH | G7: TANDA TANGAN
C8: JABATAN | D8: NILAI BROTO | E8: PPH PSL 21 (5 % ) | F8: PENERIMAAN
F9: BERSIH
A10: 1 | B10: =1+A10 -> 2 | C10: 3 | D10: 4 | E10: 5 | F10: 6 | G10: 7
A12: 1 | B12: BUDI PRIYANTO | C12: Nakhoda | D12: ='Swakelola Sangke P'!H6 -> #REF! | E12: 113078 | F12: =D12-E12 -> #REF! | G12: 1. ………..
A14: 2 | B14: ALI PAYAPO | C14: Owner Surveyor | D14: =D12 -> #REF! | E14: 12564 | F14: =D14-E14 -> #REF! | H14: 2. …………….
A16: 3 | B16: HENDRA RUDOLF SOUMOKIL | C16: KKM | D16: =D14 -> #REF! | E16: 100513 | F16: =D16-E16 -> #REF! | G16: 3. ………..
A18: 4 | B18: HARTONO BACHRUN | C18: Mualim I | D18: ='Swakelola Sangke P'!H7 -> #REF! | E18: 73291 | F18: =D18-E18 -> #REF! | H18: 4. …………….
A20: 5 | B20: DANIEL FRETS SITANIAPESSY | C20: Masinis II | D20: =D18 -> #REF! | E20: 73291 | F20: =D20-E20 -> #REF! | G20: 5. ………..
A22: 6 | B22: HARLY SETIAWAN | C22: Mualim II | D22: ='Swakelola Sangke P'!H8 -> #REF! | E22: 53398 | F22: =D22-E22 -> #REF! | H22: 6. …………….
A24: 7 | B24: NURHADI | C24: Masinis III | D24: =D22 -> #REF! | E24: 44498 | F24: =D24-E24 -> #REF! | G24: 7. …………
A26: 8 | B26: ANANG SUMARDIYONO | C26: Mualim III | D26: =D24 -> #REF! | E26: 35599 | F26: =D26-E26 -> #REF! | G26: . | H26: 8. ……………
A28: 9 | B28: ABDULLAH | C28: Masinis IV | D28: =D26 -> #REF! | E28: 35599 | F28: =D28-E28 -> #REF! | G28: 9. …………
A30: 10 | B30: WAHYU SUSILO | C30: Mandor Mesin | D30: ='Swakelola Sangke P'!H9 -> #REF! | E30: 7329 | F30: =D30-E30 -> #REF! | H30: 10. ……………
A32: 11 | B32: CRISTIANTO NIEL TAKAYA | C32: Serang | D32: ='Daftar Swakelola'!D30 -> #REF! | E32: 7329 | F32: =D32-E32 -> #REF! | G32: 11…………….
A34: 12 | B34: MUJIANTO | C34: Juru Mudi | D34: ='Swakelola Sangke P'!H10 -> #REF! | E34: 13611 | F34: =D34-E34 -> #REF! | H34: 12. ……………
A36: 13 | B36: SYAFRIN HARUNA | C36: Juru Mudi | D36: =D34 -> #REF! | E36: 10208 | F36: =D36-E36 -> #REF! | G36: 13………………
A38: 14 | B38: ASER MATIAS KENA | C38: Juru Mudi | D38: =D36 -> #REF! | E38: 10208 | F38: =D38-E38 -> #REF! | H38: 14………………
A40: 15 | B40: RASWAN ZAHIM | C40: Juru Minyak | D40: =D38 -> #REF! | E40: 10208 | F40: =D40-E40 -> #REF! | G40: 15…....................
A42: 16 | B42: AJIS SETIAWAN | C42: Juru Minyak | D42: =D40 -> #REF! | E42: 10208 | F42: =D42-E42 -> #REF!
H43: 16…....................
A44: 17 | B44: ZULFITRI LESTUSEN | C44: Juru Minyak | D44: =D42 -> #REF! | E44: 6806 | F44: =D44-E44 -> #REF!
G45: 17…....................
A46: 18 | B46: REYNALDI LAHANSANG | C46: Juru Minyak | D46: =D44 -> #REF! | E46: 6806 | F46: =D46-E46 -> #REF!
H47: 18…....................
A48: 19 | B48: MULIADI | C48: Kelasi | D48: ='Swakelola Sangke P'!H11 -> #REF! | E48: 10994 | F48: =D48-E48 -> #REF!
G49: 19…....................
A50: 20 | B50: IMAM WAHYUDI | C50: Kelasi | D50: =D48 -> #REF! | E50: 9423 | F50: =D50-E50 -> #REF!
H51: 20…....................
A52: 21 | B52: FERY INDRAWAN | C52: Juru Masak | D52: =D48 -> #REF! | E52: 10994 | F52: =D52-E52 -> #REF!
G53: 21…....................
B55: JUMLAH | D55: =SUM(D12:D54) -> #REF! | E55: =SUM(E12:E54) -> 655955 | F55: =SUM(F12:F54) -> #REF!
A57: Terbilang : #Enam Belas Juta Delapan Ratus Delapan Puluh Satu Ribu Lima Ratus Empat Puluh Lima Rupiah#
G58: Ternate, 04 Februari 2025
A60: Disetujui : | D60: Diperksa : | G60: Dibuat :
A61: General Manager | D61: Manager Teknik | G61: Staf Teknik
A67: HANDOYO PRIYANTO | D67: ERYANTO SIDABALOK | G67: IRSAN ANUGRAH
...
